2025-06-19 09:15:37 - INFO - Application started
2025-06-19 09:22:23 - INFO - Application started
2025-06-19 11:08:10 - INFO - Application started
2025-06-19 11:41:23 - INFO - Application started
2025-06-19 11:41:23 - ERROR - Failed to load tabs
Traceback (most recent call last):
  File "C:\Users\int.nimeth\Desktop\codePuls_collector\app.py", line 50, in setup_tabs
    from tabs.project_tab import setup_project_tab
  File "C:\Users\int.nimeth\Desktop\codePuls_collector\tabs\project_tab.py", line 6, in <module>
    from providers import ProviderFactory, ProviderType
  File "C:\Users\int.nimeth\Desktop\codePuls_collector\providers\__init__.py", line 3, in <module>
    from .azure_devops_provider import AzureDevOpsProvider
  File "C:\Users\int.nimeth\Desktop\codePuls_collector\providers\azure_devops_provider.py", line 12, in <module>
    from services.azure_devops.get_pr_data_service import get_pr_data_service
ImportError: cannot import name 'get_pr_data_service' from 'services.azure_devops.get_pr_data_service' (C:\Users\int.nimeth\Desktop\codePuls_collector\services\azure_devops\get_pr_data_service.py)
2025-06-19 11:41:24 - ERROR - Unhandled exception occurred
Traceback (most recent call last):
  File "C:\Users\int.nimeth\Desktop\codePuls_collector\app.py", line 50, in setup_tabs
    from tabs.project_tab import setup_project_tab
  File "C:\Users\int.nimeth\Desktop\codePuls_collector\tabs\project_tab.py", line 6, in <module>
    from providers import ProviderFactory, ProviderType
  File "C:\Users\int.nimeth\Desktop\codePuls_collector\providers\__init__.py", line 3, in <module>
    from .azure_devops_provider import AzureDevOpsProvider
  File "C:\Users\int.nimeth\Desktop\codePuls_collector\providers\azure_devops_provider.py", line 12, in <module>
    from services.azure_devops.get_pr_data_service import get_pr_data_service
ImportError: cannot import name 'get_pr_data_service' from 'services.azure_devops.get_pr_data_service' (C:\Users\int.nimeth\Desktop\codePuls_collector\services\azure_devops\get_pr_data_service.py)

During handling of the above exception, another exception occurred:

Traceback (most recent call last):
  File "C:\Users\int.nimeth\Desktop\codePuls_collector\main.py", line 12, in main
    window = SourceProviderTool()
  File "C:\Users\int.nimeth\Desktop\codePuls_collector\app.py", line 15, in __init__
    self.init_ui()
    ~~~~~~~~~~~~^^
  File "C:\Users\int.nimeth\Desktop\codePuls_collector\app.py", line 39, in init_ui
    self.setup_tabs()
    ~~~~~~~~~~~~~~~^^
  File "C:\Users\int.nimeth\Desktop\codePuls_collector\app.py", line 68, in setup_tabs
    show_error_message(str(e))
    ~~~~~~~~~~~~~~~~~~^^^^^^^^
TypeError: show_error_message() missing 1 required positional argument: 'error'
2025-06-19 11:42:19 - INFO - Application started
2025-06-19 11:42:59 - INFO - Application started
2025-06-19 11:51:10 - INFO - Application started
2025-06-23 10:15:26 - INFO - Application started
2025-06-23 14:29:53 - INFO - Application started
2025-06-23 14:31:04 - INFO - Application started
2025-06-23 14:32:55 - INFO - Application started
2025-06-23 15:31:39 - INFO - Application started
2025-06-23 16:05:53 - ERROR - Network error occurred during API request
Traceback (most recent call last):
  File "C:\Users\int.nimeth\AppData\Local\Programs\Python\Python313\Lib\site-packages\urllib3\connection.py", line 198, in _new_conn
    sock = connection.create_connection(
        (self._dns_host, self.port),
    ...<2 lines>...
        socket_options=self.socket_options,
    )
  File "C:\Users\int.nimeth\AppData\Local\Programs\Python\Python313\Lib\site-packages\urllib3\util\connection.py", line 85, in create_connection
    raise err
  File "C:\Users\int.nimeth\AppData\Local\Programs\Python\Python313\Lib\site-packages\urllib3\util\connection.py", line 73, in create_connection
    sock.connect(sa)
    ~~~~~~~~~~~~^^^^
ConnectionRefusedError: [WinError 10061] No connection could be made because the target machine actively refused it

The above exception was the direct cause of the following exception:

Traceback (most recent call last):
  File "C:\Users\int.nimeth\AppData\Local\Programs\Python\Python313\Lib\site-packages\urllib3\connectionpool.py", line 787, in urlopen
    response = self._make_request(
        conn,
    ...<10 lines>...
        **response_kw,
    )
  File "C:\Users\int.nimeth\AppData\Local\Programs\Python\Python313\Lib\site-packages\urllib3\connectionpool.py", line 493, in _make_request
    conn.request(
    ~~~~~~~~~~~~^
        method,
        ^^^^^^^
    ...<6 lines>...
        enforce_content_length=enforce_content_length,
        ^^^^^^^^^^^^^^^^^^^^^^^^^^^^^^^^^^^^^^^^^^^^^^
    )
    ^
  File "C:\Users\int.nimeth\AppData\Local\Programs\Python\Python313\Lib\site-packages\urllib3\connection.py", line 445, in request
    self.endheaders()
    ~~~~~~~~~~~~~~~^^
  File "C:\Users\int.nimeth\AppData\Local\Programs\Python\Python313\Lib\http\client.py", line 1333, in endheaders
    self._send_output(message_body, encode_chunked=encode_chunked)
    ~~~~~~~~~~~~~~~~~^^^^^^^^^^^^^^^^^^^^^^^^^^^^^^^^^^^^^^^^^^^^^
  File "C:\Users\int.nimeth\AppData\Local\Programs\Python\Python313\Lib\http\client.py", line 1093, in _send_output
    self.send(msg)
    ~~~~~~~~~^^^^^
  File "C:\Users\int.nimeth\AppData\Local\Programs\Python\Python313\Lib\http\client.py", line 1037, in send
    self.connect()
    ~~~~~~~~~~~~^^
  File "C:\Users\int.nimeth\AppData\Local\Programs\Python\Python313\Lib\site-packages\urllib3\connection.py", line 276, in connect
    self.sock = self._new_conn()
                ~~~~~~~~~~~~~~^^
  File "C:\Users\int.nimeth\AppData\Local\Programs\Python\Python313\Lib\site-packages\urllib3\connection.py", line 213, in _new_conn
    raise NewConnectionError(
        self, f"Failed to establish a new connection: {e}"
    ) from e
urllib3.exceptions.NewConnectionError: <urllib3.connection.HTTPConnection object at 0x000002ABA9D56690>: Failed to establish a new connection: [WinError 10061] No connection could be made because the target machine actively refused it

The above exception was the direct cause of the following exception:

Traceback (most recent call last):
  File "C:\Users\int.nimeth\AppData\Local\Programs\Python\Python313\Lib\site-packages\requests\adapters.py", line 667, in send
    resp = conn.urlopen(
        method=request.method,
    ...<9 lines>...
        chunked=chunked,
    )
  File "C:\Users\int.nimeth\AppData\Local\Programs\Python\Python313\Lib\site-packages\urllib3\connectionpool.py", line 841, in urlopen
    retries = retries.increment(
        method, url, error=new_e, _pool=self, _stacktrace=sys.exc_info()[2]
    )
  File "C:\Users\int.nimeth\AppData\Local\Programs\Python\Python313\Lib\site-packages\urllib3\util\retry.py", line 519, in increment
    raise MaxRetryError(_pool, url, reason) from reason  # type: ignore[arg-type]
    ^^^^^^^^^^^^^^^^^^^^^^^^^^^^^^^^^^^^^^^^^^^^^^^^^^^
urllib3.exceptions.MaxRetryError: HTTPConnectionPool(host='localhost', port=5113): Max retries exceeded with url: /api/project (Caused by NewConnectionError('<urllib3.connection.HTTPConnection object at 0x000002ABA9D56690>: Failed to establish a new connection: [WinError 10061] No connection could be made because the target machine actively refused it'))

During handling of the above exception, another exception occurred:

Traceback (most recent call last):
  File "C:\Users\int.nimeth\Desktop\codePuls_collector\services\backend\save_organization_data_service.py", line 9, in save_organization_data_service
    response = requests.post(
        USER_API["create_project"],
    ...<2 lines>...
        timeout=10
    )
  File "C:\Users\int.nimeth\AppData\Local\Programs\Python\Python313\Lib\site-packages\requests\api.py", line 115, in post
    return request("post", url, data=data, json=json, **kwargs)
  File "C:\Users\int.nimeth\AppData\Local\Programs\Python\Python313\Lib\site-packages\requests\api.py", line 59, in request
    return session.request(method=method, url=url, **kwargs)
           ~~~~~~~~~~~~~~~^^^^^^^^^^^^^^^^^^^^^^^^^^^^^^^^^^
  File "C:\Users\int.nimeth\AppData\Local\Programs\Python\Python313\Lib\site-packages\requests\sessions.py", line 589, in request
    resp = self.send(prep, **send_kwargs)
  File "C:\Users\int.nimeth\AppData\Local\Programs\Python\Python313\Lib\site-packages\requests\sessions.py", line 703, in send
    r = adapter.send(request, **kwargs)
  File "C:\Users\int.nimeth\AppData\Local\Programs\Python\Python313\Lib\site-packages\requests\adapters.py", line 700, in send
    raise ConnectionError(e, request=request)
requests.exceptions.ConnectionError: HTTPConnectionPool(host='localhost', port=5113): Max retries exceeded with url: /api/project (Caused by NewConnectionError('<urllib3.connection.HTTPConnection object at 0x000002ABA9D56690>: Failed to establish a new connection: [WinError 10061] No connection could be made because the target machine actively refused it'))
2025-06-23 16:06:14 - INFO - Application started
2025-07-02 08:38:02 - INFO - Application started
2025-07-02 08:38:25 - ERROR - API Error: A database error occurred. Please try again later.
2025-07-02 08:39:39 - ERROR - API Error: A database error occurred. Please try again later.
2025-07-02 09:00:42 - INFO - Application started
2025-07-02 10:00:06 - INFO - Application started
2025-07-03 10:31:38 - INFO - Application started
2025-07-03 11:01:41 - INFO - Application started
2025-07-03 11:07:17 - INFO - Application started
2025-07-03 11:12:44 - INFO - Application started
2025-07-03 11:15:51 - INFO - Application started
2025-07-03 11:17:42 - INFO - Application started
2025-07-03 13:00:01 - ERROR - Network error occurred during API request
Traceback (most recent call last):
  File "C:\Users\int.nimeth\AppData\Local\Programs\Python\Python313\Lib\site-packages\urllib3\connection.py", line 198, in _new_conn
    sock = connection.create_connection(
        (self._dns_host, self.port),
    ...<2 lines>...
        socket_options=self.socket_options,
    )
  File "C:\Users\int.nimeth\AppData\Local\Programs\Python\Python313\Lib\site-packages\urllib3\util\connection.py", line 85, in create_connection
    raise err
  File "C:\Users\int.nimeth\AppData\Local\Programs\Python\Python313\Lib\site-packages\urllib3\util\connection.py", line 73, in create_connection
    sock.connect(sa)
    ~~~~~~~~~~~~^^^^
ConnectionRefusedError: [WinError 10061] No connection could be made because the target machine actively refused it

The above exception was the direct cause of the following exception:

Traceback (most recent call last):
  File "C:\Users\int.nimeth\AppData\Local\Programs\Python\Python313\Lib\site-packages\urllib3\connectionpool.py", line 787, in urlopen
    response = self._make_request(
        conn,
    ...<10 lines>...
        **response_kw,
    )
  File "C:\Users\int.nimeth\AppData\Local\Programs\Python\Python313\Lib\site-packages\urllib3\connectionpool.py", line 493, in _make_request
    conn.request(
    ~~~~~~~~~~~~^
        method,
        ^^^^^^^
    ...<6 lines>...
        enforce_content_length=enforce_content_length,
        ^^^^^^^^^^^^^^^^^^^^^^^^^^^^^^^^^^^^^^^^^^^^^^
    )
    ^
  File "C:\Users\int.nimeth\AppData\Local\Programs\Python\Python313\Lib\site-packages\urllib3\connection.py", line 445, in request
    self.endheaders()
    ~~~~~~~~~~~~~~~^^
  File "C:\Users\int.nimeth\AppData\Local\Programs\Python\Python313\Lib\http\client.py", line 1333, in endheaders
    self._send_output(message_body, encode_chunked=encode_chunked)
    ~~~~~~~~~~~~~~~~~^^^^^^^^^^^^^^^^^^^^^^^^^^^^^^^^^^^^^^^^^^^^^
  File "C:\Users\int.nimeth\AppData\Local\Programs\Python\Python313\Lib\http\client.py", line 1093, in _send_output
    self.send(msg)
    ~~~~~~~~~^^^^^
  File "C:\Users\int.nimeth\AppData\Local\Programs\Python\Python313\Lib\http\client.py", line 1037, in send
    self.connect()
    ~~~~~~~~~~~~^^
  File "C:\Users\int.nimeth\AppData\Local\Programs\Python\Python313\Lib\site-packages\urllib3\connection.py", line 276, in connect
    self.sock = self._new_conn()
                ~~~~~~~~~~~~~~^^
  File "C:\Users\int.nimeth\AppData\Local\Programs\Python\Python313\Lib\site-packages\urllib3\connection.py", line 213, in _new_conn
    raise NewConnectionError(
        self, f"Failed to establish a new connection: {e}"
    ) from e
urllib3.exceptions.NewConnectionError: <urllib3.connection.HTTPConnection object at 0x000002523E625BF0>: Failed to establish a new connection: [WinError 10061] No connection could be made because the target machine actively refused it

The above exception was the direct cause of the following exception:

Traceback (most recent call last):
  File "C:\Users\int.nimeth\AppData\Local\Programs\Python\Python313\Lib\site-packages\requests\adapters.py", line 667, in send
    resp = conn.urlopen(
        method=request.method,
    ...<9 lines>...
        chunked=chunked,
    )
  File "C:\Users\int.nimeth\AppData\Local\Programs\Python\Python313\Lib\site-packages\urllib3\connectionpool.py", line 841, in urlopen
    retries = retries.increment(
        method, url, error=new_e, _pool=self, _stacktrace=sys.exc_info()[2]
    )
  File "C:\Users\int.nimeth\AppData\Local\Programs\Python\Python313\Lib\site-packages\urllib3\util\retry.py", line 519, in increment
    raise MaxRetryError(_pool, url, reason) from reason  # type: ignore[arg-type]
    ^^^^^^^^^^^^^^^^^^^^^^^^^^^^^^^^^^^^^^^^^^^^^^^^^^^
urllib3.exceptions.MaxRetryError: HTTPConnectionPool(host='localhost', port=5113): Max retries exceeded with url: /api/user (Caused by NewConnectionError('<urllib3.connection.HTTPConnection object at 0x000002523E625BF0>: Failed to establish a new connection: [WinError 10061] No connection could be made because the target machine actively refused it'))

During handling of the above exception, another exception occurred:

Traceback (most recent call last):
  File "C:\Users\int.nimeth\Desktop\codePuls_collector\services\backend\save_user_data_service.py", line 9, in save_user_data_service
    response = requests.post(
        USER_API["create_user"],
    ...<2 lines>...
        timeout=10
    )
  File "C:\Users\int.nimeth\AppData\Local\Programs\Python\Python313\Lib\site-packages\requests\api.py", line 115, in post
    return request("post", url, data=data, json=json, **kwargs)
  File "C:\Users\int.nimeth\AppData\Local\Programs\Python\Python313\Lib\site-packages\requests\api.py", line 59, in request
    return session.request(method=method, url=url, **kwargs)
           ~~~~~~~~~~~~~~~^^^^^^^^^^^^^^^^^^^^^^^^^^^^^^^^^^
  File "C:\Users\int.nimeth\AppData\Local\Programs\Python\Python313\Lib\site-packages\requests\sessions.py", line 589, in request
    resp = self.send(prep, **send_kwargs)
  File "C:\Users\int.nimeth\AppData\Local\Programs\Python\Python313\Lib\site-packages\requests\sessions.py", line 703, in send
    r = adapter.send(request, **kwargs)
  File "C:\Users\int.nimeth\AppData\Local\Programs\Python\Python313\Lib\site-packages\requests\adapters.py", line 700, in send
    raise ConnectionError(e, request=request)
requests.exceptions.ConnectionError: HTTPConnectionPool(host='localhost', port=5113): Max retries exceeded with url: /api/user (Caused by NewConnectionError('<urllib3.connection.HTTPConnection object at 0x000002523E625BF0>: Failed to establish a new connection: [WinError 10061] No connection could be made because the target machine actively refused it'))
2025-07-03 13:03:25 - INFO - Application started
2025-07-03 13:03:43 - ERROR - Network error occurred during API request
Traceback (most recent call last):
  File "C:\Users\int.nimeth\AppData\Local\Programs\Python\Python313\Lib\site-packages\urllib3\connection.py", line 198, in _new_conn
    sock = connection.create_connection(
        (self._dns_host, self.port),
    ...<2 lines>...
        socket_options=self.socket_options,
    )
  File "C:\Users\int.nimeth\AppData\Local\Programs\Python\Python313\Lib\site-packages\urllib3\util\connection.py", line 85, in create_connection
    raise err
  File "C:\Users\int.nimeth\AppData\Local\Programs\Python\Python313\Lib\site-packages\urllib3\util\connection.py", line 73, in create_connection
    sock.connect(sa)
    ~~~~~~~~~~~~^^^^
ConnectionRefusedError: [WinError 10061] No connection could be made because the target machine actively refused it

The above exception was the direct cause of the following exception:

Traceback (most recent call last):
  File "C:\Users\int.nimeth\AppData\Local\Programs\Python\Python313\Lib\site-packages\urllib3\connectionpool.py", line 787, in urlopen
    response = self._make_request(
        conn,
    ...<10 lines>...
        **response_kw,
    )
  File "C:\Users\int.nimeth\AppData\Local\Programs\Python\Python313\Lib\site-packages\urllib3\connectionpool.py", line 493, in _make_request
    conn.request(
    ~~~~~~~~~~~~^
        method,
        ^^^^^^^
    ...<6 lines>...
        enforce_content_length=enforce_content_length,
        ^^^^^^^^^^^^^^^^^^^^^^^^^^^^^^^^^^^^^^^^^^^^^^
    )
    ^
  File "C:\Users\int.nimeth\AppData\Local\Programs\Python\Python313\Lib\site-packages\urllib3\connection.py", line 445, in request
    self.endheaders()
    ~~~~~~~~~~~~~~~^^
  File "C:\Users\int.nimeth\AppData\Local\Programs\Python\Python313\Lib\http\client.py", line 1333, in endheaders
    self._send_output(message_body, encode_chunked=encode_chunked)
    ~~~~~~~~~~~~~~~~~^^^^^^^^^^^^^^^^^^^^^^^^^^^^^^^^^^^^^^^^^^^^^
  File "C:\Users\int.nimeth\AppData\Local\Programs\Python\Python313\Lib\http\client.py", line 1093, in _send_output
    self.send(msg)
    ~~~~~~~~~^^^^^
  File "C:\Users\int.nimeth\AppData\Local\Programs\Python\Python313\Lib\http\client.py", line 1037, in send
    self.connect()
    ~~~~~~~~~~~~^^
  File "C:\Users\int.nimeth\AppData\Local\Programs\Python\Python313\Lib\site-packages\urllib3\connection.py", line 276, in connect
    self.sock = self._new_conn()
                ~~~~~~~~~~~~~~^^
  File "C:\Users\int.nimeth\AppData\Local\Programs\Python\Python313\Lib\site-packages\urllib3\connection.py", line 213, in _new_conn
    raise NewConnectionError(
        self, f"Failed to establish a new connection: {e}"
    ) from e
urllib3.exceptions.NewConnectionError: <urllib3.connection.HTTPConnection object at 0x0000027F4E656A50>: Failed to establish a new connection: [WinError 10061] No connection could be made because the target machine actively refused it

The above exception was the direct cause of the following exception:

Traceback (most recent call last):
  File "C:\Users\int.nimeth\AppData\Local\Programs\Python\Python313\Lib\site-packages\requests\adapters.py", line 667, in send
    resp = conn.urlopen(
        method=request.method,
    ...<9 lines>...
        chunked=chunked,
    )
  File "C:\Users\int.nimeth\AppData\Local\Programs\Python\Python313\Lib\site-packages\urllib3\connectionpool.py", line 841, in urlopen
    retries = retries.increment(
        method, url, error=new_e, _pool=self, _stacktrace=sys.exc_info()[2]
    )
  File "C:\Users\int.nimeth\AppData\Local\Programs\Python\Python313\Lib\site-packages\urllib3\util\retry.py", line 519, in increment
    raise MaxRetryError(_pool, url, reason) from reason  # type: ignore[arg-type]
    ^^^^^^^^^^^^^^^^^^^^^^^^^^^^^^^^^^^^^^^^^^^^^^^^^^^
urllib3.exceptions.MaxRetryError: HTTPConnectionPool(host='localhost', port=5113): Max retries exceeded with url: /api/project (Caused by NewConnectionError('<urllib3.connection.HTTPConnection object at 0x0000027F4E656A50>: Failed to establish a new connection: [WinError 10061] No connection could be made because the target machine actively refused it'))

During handling of the above exception, another exception occurred:

Traceback (most recent call last):
  File "C:\Users\int.nimeth\Desktop\codePuls_collector\services\backend\save_organization_data_service.py", line 9, in save_organization_data_service
    response = requests.post(
        USER_API["create_project"],
    ...<2 lines>...
        timeout=10
    )
  File "C:\Users\int.nimeth\AppData\Local\Programs\Python\Python313\Lib\site-packages\requests\api.py", line 115, in post
    return request("post", url, data=data, json=json, **kwargs)
  File "C:\Users\int.nimeth\AppData\Local\Programs\Python\Python313\Lib\site-packages\requests\api.py", line 59, in request
    return session.request(method=method, url=url, **kwargs)
           ~~~~~~~~~~~~~~~^^^^^^^^^^^^^^^^^^^^^^^^^^^^^^^^^^
  File "C:\Users\int.nimeth\AppData\Local\Programs\Python\Python313\Lib\site-packages\requests\sessions.py", line 589, in request
    resp = self.send(prep, **send_kwargs)
  File "C:\Users\int.nimeth\AppData\Local\Programs\Python\Python313\Lib\site-packages\requests\sessions.py", line 703, in send
    r = adapter.send(request, **kwargs)
  File "C:\Users\int.nimeth\AppData\Local\Programs\Python\Python313\Lib\site-packages\requests\adapters.py", line 700, in send
    raise ConnectionError(e, request=request)
requests.exceptions.ConnectionError: HTTPConnectionPool(host='localhost', port=5113): Max retries exceeded with url: /api/project (Caused by NewConnectionError('<urllib3.connection.HTTPConnection object at 0x0000027F4E656A50>: Failed to establish a new connection: [WinError 10061] No connection could be made because the target machine actively refused it'))
2025-07-03 13:05:04 - INFO - Application started
2025-07-03 14:15:48 - INFO - Application started
2025-07-03 14:16:07 - ERROR - Network error occurred during API request
Traceback (most recent call last):
  File "C:\Users\int.nimeth\AppData\Local\Programs\Python\Python313\Lib\site-packages\urllib3\connection.py", line 198, in _new_conn
    sock = connection.create_connection(
        (self._dns_host, self.port),
    ...<2 lines>...
        socket_options=self.socket_options,
    )
  File "C:\Users\int.nimeth\AppData\Local\Programs\Python\Python313\Lib\site-packages\urllib3\util\connection.py", line 85, in create_connection
    raise err
  File "C:\Users\int.nimeth\AppData\Local\Programs\Python\Python313\Lib\site-packages\urllib3\util\connection.py", line 73, in create_connection
    sock.connect(sa)
    ~~~~~~~~~~~~^^^^
ConnectionRefusedError: [WinError 10061] No connection could be made because the target machine actively refused it

The above exception was the direct cause of the following exception:

Traceback (most recent call last):
  File "C:\Users\int.nimeth\AppData\Local\Programs\Python\Python313\Lib\site-packages\urllib3\connectionpool.py", line 787, in urlopen
    response = self._make_request(
        conn,
    ...<10 lines>...
        **response_kw,
    )
  File "C:\Users\int.nimeth\AppData\Local\Programs\Python\Python313\Lib\site-packages\urllib3\connectionpool.py", line 493, in _make_request
    conn.request(
    ~~~~~~~~~~~~^
        method,
        ^^^^^^^
    ...<6 lines>...
        enforce_content_length=enforce_content_length,
        ^^^^^^^^^^^^^^^^^^^^^^^^^^^^^^^^^^^^^^^^^^^^^^
    )
    ^
  File "C:\Users\int.nimeth\AppData\Local\Programs\Python\Python313\Lib\site-packages\urllib3\connection.py", line 445, in request
    self.endheaders()
    ~~~~~~~~~~~~~~~^^
  File "C:\Users\int.nimeth\AppData\Local\Programs\Python\Python313\Lib\http\client.py", line 1333, in endheaders
    self._send_output(message_body, encode_chunked=encode_chunked)
    ~~~~~~~~~~~~~~~~~^^^^^^^^^^^^^^^^^^^^^^^^^^^^^^^^^^^^^^^^^^^^^
  File "C:\Users\int.nimeth\AppData\Local\Programs\Python\Python313\Lib\http\client.py", line 1093, in _send_output
    self.send(msg)
    ~~~~~~~~~^^^^^
  File "C:\Users\int.nimeth\AppData\Local\Programs\Python\Python313\Lib\http\client.py", line 1037, in send
    self.connect()
    ~~~~~~~~~~~~^^
  File "C:\Users\int.nimeth\AppData\Local\Programs\Python\Python313\Lib\site-packages\urllib3\connection.py", line 276, in connect
    self.sock = self._new_conn()
                ~~~~~~~~~~~~~~^^
  File "C:\Users\int.nimeth\AppData\Local\Programs\Python\Python313\Lib\site-packages\urllib3\connection.py", line 213, in _new_conn
    raise NewConnectionError(
        self, f"Failed to establish a new connection: {e}"
    ) from e
urllib3.exceptions.NewConnectionError: <urllib3.connection.HTTPConnection object at 0x000002823089EBA0>: Failed to establish a new connection: [WinError 10061] No connection could be made because the target machine actively refused it

The above exception was the direct cause of the following exception:

Traceback (most recent call last):
  File "C:\Users\int.nimeth\AppData\Local\Programs\Python\Python313\Lib\site-packages\requests\adapters.py", line 667, in send
    resp = conn.urlopen(
        method=request.method,
    ...<9 lines>...
        chunked=chunked,
    )
  File "C:\Users\int.nimeth\AppData\Local\Programs\Python\Python313\Lib\site-packages\urllib3\connectionpool.py", line 841, in urlopen
    retries = retries.increment(
        method, url, error=new_e, _pool=self, _stacktrace=sys.exc_info()[2]
    )
  File "C:\Users\int.nimeth\AppData\Local\Programs\Python\Python313\Lib\site-packages\urllib3\util\retry.py", line 519, in increment
    raise MaxRetryError(_pool, url, reason) from reason  # type: ignore[arg-type]
    ^^^^^^^^^^^^^^^^^^^^^^^^^^^^^^^^^^^^^^^^^^^^^^^^^^^
urllib3.exceptions.MaxRetryError: HTTPConnectionPool(host='localhost', port=5113): Max retries exceeded with url: /api/project (Caused by NewConnectionError('<urllib3.connection.HTTPConnection object at 0x000002823089EBA0>: Failed to establish a new connection: [WinError 10061] No connection could be made because the target machine actively refused it'))

During handling of the above exception, another exception occurred:

Traceback (most recent call last):
  File "C:\Users\int.nimeth\Desktop\codePuls_collector\services\backend\save_organization_data_service.py", line 9, in save_organization_data_service
    response = requests.post(
        USER_API["create_project"],
    ...<2 lines>...
        timeout=10
    )
  File "C:\Users\int.nimeth\AppData\Local\Programs\Python\Python313\Lib\site-packages\requests\api.py", line 115, in post
    return request("post", url, data=data, json=json, **kwargs)
  File "C:\Users\int.nimeth\AppData\Local\Programs\Python\Python313\Lib\site-packages\requests\api.py", line 59, in request
    return session.request(method=method, url=url, **kwargs)
           ~~~~~~~~~~~~~~~^^^^^^^^^^^^^^^^^^^^^^^^^^^^^^^^^^
  File "C:\Users\int.nimeth\AppData\Local\Programs\Python\Python313\Lib\site-packages\requests\sessions.py", line 589, in request
    resp = self.send(prep, **send_kwargs)
  File "C:\Users\int.nimeth\AppData\Local\Programs\Python\Python313\Lib\site-packages\requests\sessions.py", line 703, in send
    r = adapter.send(request, **kwargs)
  File "C:\Users\int.nimeth\AppData\Local\Programs\Python\Python313\Lib\site-packages\requests\adapters.py", line 700, in send
    raise ConnectionError(e, request=request)
requests.exceptions.ConnectionError: HTTPConnectionPool(host='localhost', port=5113): Max retries exceeded with url: /api/project (Caused by NewConnectionError('<urllib3.connection.HTTPConnection object at 0x000002823089EBA0>: Failed to establish a new connection: [WinError 10061] No connection could be made because the target machine actively refused it'))
2025-07-03 14:56:05 - INFO - Application started
2025-07-03 15:06:23 - INFO - Application started
2025-07-03 15:23:58 - INFO - Application started
2025-07-03 15:33:45 - INFO - Application started
2025-07-03 15:37:53 - INFO - Application started
2025-07-03 15:37:53 - ERROR - Failed to load tabs
Traceback (most recent call last):
  File "C:\Users\int.nimeth\Desktop\codePuls_collector\app.py", line 61, in setup_tabs
    self.tab_widget.addTab(setup_user_tab(self), "Users")
                           ~~~~~~~~~~~~~~^^^^^^
  File "C:\Users\int.nimeth\Desktop\codePuls_collector\tabs\user_tab.py", line 68, in setup_user_tab
    parent.teams_progress_bar.setVisible(True)
    ^^^^^^^^^^^^^^^^^^^^^^^^^
AttributeError: 'SourceProviderTool' object has no attribute 'teams_progress_bar'. Did you mean: 'users_progress_bar'?
2025-07-03 15:37:53 - ERROR - Unhandled exception occurred
Traceback (most recent call last):
  File "C:\Users\int.nimeth\Desktop\codePuls_collector\app.py", line 61, in setup_tabs
    self.tab_widget.addTab(setup_user_tab(self), "Users")
                           ~~~~~~~~~~~~~~^^^^^^
  File "C:\Users\int.nimeth\Desktop\codePuls_collector\tabs\user_tab.py", line 68, in setup_user_tab
    parent.teams_progress_bar.setVisible(True)
    ^^^^^^^^^^^^^^^^^^^^^^^^^
AttributeError: 'SourceProviderTool' object has no attribute 'teams_progress_bar'. Did you mean: 'users_progress_bar'?

During handling of the above exception, another exception occurred:

Traceback (most recent call last):
  File "C:\Users\int.nimeth\Desktop\codePuls_collector\main.py", line 12, in main
    window = SourceProviderTool()
  File "C:\Users\int.nimeth\Desktop\codePuls_collector\app.py", line 16, in __init__
    self.init_ui()
    ~~~~~~~~~~~~^^
  File "C:\Users\int.nimeth\Desktop\codePuls_collector\app.py", line 41, in init_ui
    self.setup_tabs()
    ~~~~~~~~~~~~~~~^^
  File "C:\Users\int.nimeth\Desktop\codePuls_collector\app.py", line 70, in setup_tabs
    show_error_message(str(e))
    ~~~~~~~~~~~~~~~~~~^^^^^^^^
TypeError: show_error_message() missing 1 required positional argument: 'error'
2025-07-03 15:38:16 - INFO - Application started
2025-07-03 15:40:00 - INFO - Application started
2025-07-03 15:41:27 - INFO - Application started
2025-07-04 08:54:45 - INFO - Application started
2025-07-04 09:08:18 - INFO - Application started
2025-07-04 09:16:26 - INFO - Application started
2025-07-04 09:44:21 - INFO - Application started
2025-07-04 09:45:40 - INFO - Application started
2025-07-04 09:46:16 - INFO - Application started
2025-07-04 10:02:32 - INFO - Application started
2025-07-04 10:04:45 - INFO - Application started
2025-07-04 10:15:17 - INFO - Application started
2025-07-04 10:25:22 - INFO - Application started
2025-07-04 10:43:34 - INFO - Application started
2025-07-04 10:47:51 - INFO - Application started
2025-07-04 10:55:19 - INFO - Application started
2025-07-04 11:07:58 - INFO - Application started
2025-07-04 11:41:31 - INFO - Application started
2025-07-04 11:43:35 - INFO - Application started
2025-07-04 12:03:02 - INFO - Application started
2025-07-04 13:57:22 - INFO - Application started
2025-07-04 13:57:22 - ERROR - Failed to load tabs
Traceback (most recent call last):
  File "C:\Users\int.nimeth\Desktop\codePuls_collector\app.py", line 55, in setup_tabs
    from tabs.team_member_tab import setup_team_member_tab
  File "C:\Users\int.nimeth\Desktop\codePuls_collector\tabs\team_member_tab.py", line 1, in <module>
    from PyQt6.QtWidgets import (
    ...<2 lines>...
    )
ImportError: cannot import name 'QCoreApplication' from 'PyQt6.QtWidgets' (C:\Users\int.nimeth\AppData\Local\Programs\Python\Python313\Lib\site-packages\PyQt6\QtWidgets.pyd)
2025-07-04 13:57:22 - ERROR - Unhandled exception occurred
Traceback (most recent call last):
  File "C:\Users\int.nimeth\Desktop\codePuls_collector\app.py", line 55, in setup_tabs
    from tabs.team_member_tab import setup_team_member_tab
  File "C:\Users\int.nimeth\Desktop\codePuls_collector\tabs\team_member_tab.py", line 1, in <module>
    from PyQt6.QtWidgets import (
    ...<2 lines>...
    )
ImportError: cannot import name 'QCoreApplication' from 'PyQt6.QtWidgets' (C:\Users\int.nimeth\AppData\Local\Programs\Python\Python313\Lib\site-packages\PyQt6\QtWidgets.pyd)

During handling of the above exception, another exception occurred:

Traceback (most recent call last):
  File "C:\Users\int.nimeth\Desktop\codePuls_collector\main.py", line 12, in main
    window = SourceProviderTool()
  File "C:\Users\int.nimeth\Desktop\codePuls_collector\app.py", line 16, in __init__
    self.init_ui()
    ~~~~~~~~~~~~^^
  File "C:\Users\int.nimeth\Desktop\codePuls_collector\app.py", line 41, in init_ui
    self.setup_tabs()
    ~~~~~~~~~~~~~~~^^
  File "C:\Users\int.nimeth\Desktop\codePuls_collector\app.py", line 70, in setup_tabs
    show_error_message(str(e))
    ~~~~~~~~~~~~~~~~~~^^^^^^^^
TypeError: show_error_message() missing 1 required positional argument: 'error'
2025-07-04 13:58:15 - INFO - Application started
2025-07-04 14:12:30 - INFO - Application started
2025-07-04 14:25:08 - INFO - Application started
2025-07-04 14:39:54 - INFO - Application started
2025-07-04 14:54:59 - INFO - Application started
2025-07-04 15:30:55 - INFO - Application started
2025-07-04 16:39:12 - INFO - Application started
2025-07-04 16:39:48 - INFO - Application started
2025-07-07 09:28:58 - INFO - Application started
2025-07-07 09:31:35 - INFO - Application started
2025-07-07 09:32:45 - ERROR - Network error occurred during API request
Traceback (most recent call last):
  File "C:\Users\int.nimeth\AppData\Local\Programs\Python\Python313\Lib\site-packages\urllib3\connection.py", line 198, in _new_conn
    sock = connection.create_connection(
        (self._dns_host, self.port),
    ...<2 lines>...
        socket_options=self.socket_options,
    )
  File "C:\Users\int.nimeth\AppData\Local\Programs\Python\Python313\Lib\site-packages\urllib3\util\connection.py", line 85, in create_connection
    raise err
  File "C:\Users\int.nimeth\AppData\Local\Programs\Python\Python313\Lib\site-packages\urllib3\util\connection.py", line 73, in create_connection
    sock.connect(sa)
    ~~~~~~~~~~~~^^^^
ConnectionRefusedError: [WinError 10061] No connection could be made because the target machine actively refused it

The above exception was the direct cause of the following exception:

Traceback (most recent call last):
  File "C:\Users\int.nimeth\AppData\Local\Programs\Python\Python313\Lib\site-packages\urllib3\connectionpool.py", line 787, in urlopen
    response = self._make_request(
        conn,
    ...<10 lines>...
        **response_kw,
    )
  File "C:\Users\int.nimeth\AppData\Local\Programs\Python\Python313\Lib\site-packages\urllib3\connectionpool.py", line 493, in _make_request
    conn.request(
    ~~~~~~~~~~~~^
        method,
        ^^^^^^^
    ...<6 lines>...
        enforce_content_length=enforce_content_length,
        ^^^^^^^^^^^^^^^^^^^^^^^^^^^^^^^^^^^^^^^^^^^^^^
    )
    ^
  File "C:\Users\int.nimeth\AppData\Local\Programs\Python\Python313\Lib\site-packages\urllib3\connection.py", line 445, in request
    self.endheaders()
    ~~~~~~~~~~~~~~~^^
  File "C:\Users\int.nimeth\AppData\Local\Programs\Python\Python313\Lib\http\client.py", line 1333, in endheaders
    self._send_output(message_body, encode_chunked=encode_chunked)
    ~~~~~~~~~~~~~~~~~^^^^^^^^^^^^^^^^^^^^^^^^^^^^^^^^^^^^^^^^^^^^^
  File "C:\Users\int.nimeth\AppData\Local\Programs\Python\Python313\Lib\http\client.py", line 1093, in _send_output
    self.send(msg)
    ~~~~~~~~~^^^^^
  File "C:\Users\int.nimeth\AppData\Local\Programs\Python\Python313\Lib\http\client.py", line 1037, in send
    self.connect()
    ~~~~~~~~~~~~^^
  File "C:\Users\int.nimeth\AppData\Local\Programs\Python\Python313\Lib\site-packages\urllib3\connection.py", line 276, in connect
    self.sock = self._new_conn()
                ~~~~~~~~~~~~~~^^
  File "C:\Users\int.nimeth\AppData\Local\Programs\Python\Python313\Lib\site-packages\urllib3\connection.py", line 213, in _new_conn
    raise NewConnectionError(
        self, f"Failed to establish a new connection: {e}"
    ) from e
urllib3.exceptions.NewConnectionError: <urllib3.connection.HTTPConnection object at 0x0000019385BDEF90>: Failed to establish a new connection: [WinError 10061] No connection could be made because the target machine actively refused it

The above exception was the direct cause of the following exception:

Traceback (most recent call last):
  File "C:\Users\int.nimeth\AppData\Local\Programs\Python\Python313\Lib\site-packages\requests\adapters.py", line 667, in send
    resp = conn.urlopen(
        method=request.method,
    ...<9 lines>...
        chunked=chunked,
    )
  File "C:\Users\int.nimeth\AppData\Local\Programs\Python\Python313\Lib\site-packages\urllib3\connectionpool.py", line 841, in urlopen
    retries = retries.increment(
        method, url, error=new_e, _pool=self, _stacktrace=sys.exc_info()[2]
    )
  File "C:\Users\int.nimeth\AppData\Local\Programs\Python\Python313\Lib\site-packages\urllib3\util\retry.py", line 519, in increment
    raise MaxRetryError(_pool, url, reason) from reason  # type: ignore[arg-type]
    ^^^^^^^^^^^^^^^^^^^^^^^^^^^^^^^^^^^^^^^^^^^^^^^^^^^
urllib3.exceptions.MaxRetryError: HTTPConnectionPool(host='localhost', port=5113): Max retries exceeded with url: /api/project (Caused by NewConnectionError('<urllib3.connection.HTTPConnection object at 0x0000019385BDEF90>: Failed to establish a new connection: [WinError 10061] No connection could be made because the target machine actively refused it'))

During handling of the above exception, another exception occurred:

Traceback (most recent call last):
  File "C:\Users\int.nimeth\Desktop\codePuls_collector\services\backend\save_organization_data_service.py", line 9, in save_organization_data_service
    response = requests.post(
        USER_API["create_project"],
    ...<2 lines>...
        timeout=10
    )
  File "C:\Users\int.nimeth\AppData\Local\Programs\Python\Python313\Lib\site-packages\requests\api.py", line 115, in post
    return request("post", url, data=data, json=json, **kwargs)
  File "C:\Users\int.nimeth\AppData\Local\Programs\Python\Python313\Lib\site-packages\requests\api.py", line 59, in request
    return session.request(method=method, url=url, **kwargs)
           ~~~~~~~~~~~~~~~^^^^^^^^^^^^^^^^^^^^^^^^^^^^^^^^^^
  File "C:\Users\int.nimeth\AppData\Local\Programs\Python\Python313\Lib\site-packages\requests\sessions.py", line 589, in request
    resp = self.send(prep, **send_kwargs)
  File "C:\Users\int.nimeth\AppData\Local\Programs\Python\Python313\Lib\site-packages\requests\sessions.py", line 703, in send
    r = adapter.send(request, **kwargs)
  File "C:\Users\int.nimeth\AppData\Local\Programs\Python\Python313\Lib\site-packages\requests\adapters.py", line 700, in send
    raise ConnectionError(e, request=request)
requests.exceptions.ConnectionError: HTTPConnectionPool(host='localhost', port=5113): Max retries exceeded with url: /api/project (Caused by NewConnectionError('<urllib3.connection.HTTPConnection object at 0x0000019385BDEF90>: Failed to establish a new connection: [WinError 10061] No connection could be made because the target machine actively refused it'))
2025-07-07 09:37:12 - INFO - Application started
2025-07-07 09:40:01 - INFO - Application started
2025-07-07 10:06:10 - INFO - Application started
2025-07-07 10:21:04 - INFO - Application started
2025-07-07 10:44:21 - INFO - Application started
2025-07-07 10:44:21 - ERROR - Failed to load tabs
Traceback (most recent call last):
  File "C:\Users\int.nimeth\Desktop\codePuls_collector\app.py", line 52, in setup_tabs
    from tabs.project_tab import setup_project_tab
  File "C:\Users\int.nimeth\Desktop\codePuls_collector\tabs\project_tab.py", line 5, in <module>
    from controller.project_controller import update_provider_fields,fetch_and_save_organization,clear_organization_fields
ModuleNotFoundError: No module named 'controller.project_controller'
2025-07-07 10:44:21 - ERROR - Unhandled exception occurred
Traceback (most recent call last):
  File "C:\Users\int.nimeth\Desktop\codePuls_collector\app.py", line 52, in setup_tabs
    from tabs.project_tab import setup_project_tab
  File "C:\Users\int.nimeth\Desktop\codePuls_collector\tabs\project_tab.py", line 5, in <module>
    from controller.project_controller import update_provider_fields,fetch_and_save_organization,clear_organization_fields
ModuleNotFoundError: No module named 'controller.project_controller'

During handling of the above exception, another exception occurred:

Traceback (most recent call last):
  File "C:\Users\int.nimeth\Desktop\codePuls_collector\main.py", line 12, in main
    window = SourceProviderTool()
  File "C:\Users\int.nimeth\Desktop\codePuls_collector\app.py", line 16, in __init__
    self.init_ui()
    ~~~~~~~~~~~~^^
  File "C:\Users\int.nimeth\Desktop\codePuls_collector\app.py", line 41, in init_ui
    self.setup_tabs()
    ~~~~~~~~~~~~~~~^^
  File "C:\Users\int.nimeth\Desktop\codePuls_collector\app.py", line 70, in setup_tabs
    show_error_message(str(e))
    ~~~~~~~~~~~~~~~~~~^^^^^^^^
TypeError: show_error_message() missing 1 required positional argument: 'error'
2025-07-07 10:46:42 - INFO - Application started
2025-07-07 10:46:42 - ERROR - Failed to load tabs
Traceback (most recent call last):
  File "C:\Users\int.nimeth\Desktop\codePuls_collector\app.py", line 53, in setup_tabs
    from tabs.user_tab import setup_user_tab
  File "C:\Users\int.nimeth\Desktop\codePuls_collector\tabs\user_tab.py", line 5, in <module>
    from controller.user_presenter import check_all_users,on_tab_changed,save_selected_users
  File "C:\Users\int.nimeth\Desktop\codePuls_collector\controller\user_presenter.py", line 1
    from PyQt6.QtWidgets import QWidget, QHBoxLayout, QProgressBar, QMessageBox, 
                                                                                 ^
SyntaxError: trailing comma not allowed without surrounding parentheses
2025-07-07 10:46:42 - ERROR - Unhandled exception occurred
Traceback (most recent call last):
  File "C:\Users\int.nimeth\Desktop\codePuls_collector\app.py", line 53, in setup_tabs
    from tabs.user_tab import setup_user_tab
  File "C:\Users\int.nimeth\Desktop\codePuls_collector\tabs\user_tab.py", line 5, in <module>
    from controller.user_presenter import check_all_users,on_tab_changed,save_selected_users
  File "C:\Users\int.nimeth\Desktop\codePuls_collector\controller\user_presenter.py", line 1
    from PyQt6.QtWidgets import QWidget, QHBoxLayout, QProgressBar, QMessageBox, 
                                                                                 ^
SyntaxError: trailing comma not allowed without surrounding parentheses

During handling of the above exception, another exception occurred:

Traceback (most recent call last):
  File "C:\Users\int.nimeth\Desktop\codePuls_collector\main.py", line 12, in main
    window = SourceProviderTool()
  File "C:\Users\int.nimeth\Desktop\codePuls_collector\app.py", line 16, in __init__
    self.init_ui()
    ~~~~~~~~~~~~^^
  File "C:\Users\int.nimeth\Desktop\codePuls_collector\app.py", line 41, in init_ui
    self.setup_tabs()
    ~~~~~~~~~~~~~~~^^
  File "C:\Users\int.nimeth\Desktop\codePuls_collector\app.py", line 70, in setup_tabs
    show_error_message(str(e))
    ~~~~~~~~~~~~~~~~~~^^^^^^^^
TypeError: show_error_message() missing 1 required positional argument: 'error'
2025-07-07 10:47:30 - INFO - Application started
2025-07-07 10:47:30 - ERROR - Failed to load tabs
Traceback (most recent call last):
  File "C:\Users\int.nimeth\Desktop\codePuls_collector\app.py", line 53, in setup_tabs
    from tabs.user_tab import setup_user_tab
  File "C:\Users\int.nimeth\Desktop\codePuls_collector\tabs\user_tab.py", line 5, in <module>
    from controller.user_presenter import check_all_users,on_tab_changed,save_selected_users
  File "C:\Users\int.nimeth\Desktop\codePuls_collector\controller\user_presenter.py", line 1
    from PyQt6.QtWidgets import QWidget, QHBoxLayout, QProgressBar, QMessageBox, 
                                                                                 ^
SyntaxError: trailing comma not allowed without surrounding parentheses
2025-07-07 10:47:30 - ERROR - Unhandled exception occurred
Traceback (most recent call last):
  File "C:\Users\int.nimeth\Desktop\codePuls_collector\app.py", line 53, in setup_tabs
    from tabs.user_tab import setup_user_tab
  File "C:\Users\int.nimeth\Desktop\codePuls_collector\tabs\user_tab.py", line 5, in <module>
    from controller.user_presenter import check_all_users,on_tab_changed,save_selected_users
  File "C:\Users\int.nimeth\Desktop\codePuls_collector\controller\user_presenter.py", line 1
    from PyQt6.QtWidgets import QWidget, QHBoxLayout, QProgressBar, QMessageBox, 
                                                                                 ^
SyntaxError: trailing comma not allowed without surrounding parentheses

During handling of the above exception, another exception occurred:

Traceback (most recent call last):
  File "C:\Users\int.nimeth\Desktop\codePuls_collector\main.py", line 12, in main
    window = SourceProviderTool()
  File "C:\Users\int.nimeth\Desktop\codePuls_collector\app.py", line 16, in __init__
    self.init_ui()
    ~~~~~~~~~~~~^^
  File "C:\Users\int.nimeth\Desktop\codePuls_collector\app.py", line 41, in init_ui
    self.setup_tabs()
    ~~~~~~~~~~~~~~~^^
  File "C:\Users\int.nimeth\Desktop\codePuls_collector\app.py", line 70, in setup_tabs
    show_error_message(str(e))
    ~~~~~~~~~~~~~~~~~~^^^^^^^^
TypeError: show_error_message() missing 1 required positional argument: 'error'
2025-07-07 10:48:22 - INFO - Application started
2025-07-07 10:48:22 - ERROR - Failed to load tabs
Traceback (most recent call last):
  File "C:\Users\int.nimeth\Desktop\codePuls_collector\app.py", line 53, in setup_tabs
    from tabs.user_tab import setup_user_tab
  File "C:\Users\int.nimeth\Desktop\codePuls_collector\tabs\user_tab.py", line 5, in <module>
    from controller.user_presenter import check_all_users,on_tab_changed,save_selected_users
  File "C:\Users\int.nimeth\Desktop\codePuls_collector\controller\user_presenter.py", line 1
    from PyQt6.QtWidgets import QWidget, QHBoxLayout, QProgressBar, QMessageBox, 
                                                                                 ^
SyntaxError: trailing comma not allowed without surrounding parentheses
2025-07-07 10:48:22 - ERROR - Unhandled exception occurred
Traceback (most recent call last):
  File "C:\Users\int.nimeth\Desktop\codePuls_collector\app.py", line 53, in setup_tabs
    from tabs.user_tab import setup_user_tab
  File "C:\Users\int.nimeth\Desktop\codePuls_collector\tabs\user_tab.py", line 5, in <module>
    from controller.user_presenter import check_all_users,on_tab_changed,save_selected_users
  File "C:\Users\int.nimeth\Desktop\codePuls_collector\controller\user_presenter.py", line 1
    from PyQt6.QtWidgets import QWidget, QHBoxLayout, QProgressBar, QMessageBox, 
                                                                                 ^
SyntaxError: trailing comma not allowed without surrounding parentheses

During handling of the above exception, another exception occurred:

Traceback (most recent call last):
  File "C:\Users\int.nimeth\Desktop\codePuls_collector\main.py", line 12, in main
    window = SourceProviderTool()
  File "C:\Users\int.nimeth\Desktop\codePuls_collector\app.py", line 16, in __init__
    self.init_ui()
    ~~~~~~~~~~~~^^
  File "C:\Users\int.nimeth\Desktop\codePuls_collector\app.py", line 41, in init_ui
    self.setup_tabs()
    ~~~~~~~~~~~~~~~^^
  File "C:\Users\int.nimeth\Desktop\codePuls_collector\app.py", line 70, in setup_tabs
    show_error_message(str(e))
    ~~~~~~~~~~~~~~~~~~^^^^^^^^
TypeError: show_error_message() missing 1 required positional argument: 'error'
2025-07-07 10:49:02 - INFO - Application started
2025-07-07 10:52:06 - INFO - Application started
2025-07-07 10:53:28 - INFO - Application started
2025-07-07 10:54:34 - INFO - Application started
2025-07-07 11:17:59 - INFO - Application started
2025-07-07 11:17:59 - ERROR - Failed to load tabs
Traceback (most recent call last):
  File "C:\Users\int.nimeth\Desktop\codePuls_collector\app.py", line 54, in setup_tabs
    from tabs.team_tab import setup_team_tab
  File "C:\Users\int.nimeth\Desktop\codePuls_collector\tabs\team_tab.py", line 5, in <module>
    from controller.team_controller import save_selected_teams,on_tab_changed
ModuleNotFoundError: No module named 'controller.team_controller'
2025-07-07 11:17:59 - ERROR - Unhandled exception occurred
Traceback (most recent call last):
  File "C:\Users\int.nimeth\Desktop\codePuls_collector\app.py", line 54, in setup_tabs
    from tabs.team_tab import setup_team_tab
  File "C:\Users\int.nimeth\Desktop\codePuls_collector\tabs\team_tab.py", line 5, in <module>
    from controller.team_controller import save_selected_teams,on_tab_changed
ModuleNotFoundError: No module named 'controller.team_controller'

During handling of the above exception, another exception occurred:

Traceback (most recent call last):
  File "C:\Users\int.nimeth\Desktop\codePuls_collector\main.py", line 12, in main
    window = SourceProviderTool()
  File "C:\Users\int.nimeth\Desktop\codePuls_collector\app.py", line 16, in __init__
    self.init_ui()
    ~~~~~~~~~~~~^^
  File "C:\Users\int.nimeth\Desktop\codePuls_collector\app.py", line 41, in init_ui
    self.setup_tabs()
    ~~~~~~~~~~~~~~~^^
  File "C:\Users\int.nimeth\Desktop\codePuls_collector\app.py", line 70, in setup_tabs
    show_error_message(str(e))
    ~~~~~~~~~~~~~~~~~~^^^^^^^^
TypeError: show_error_message() missing 1 required positional argument: 'error'
2025-07-07 11:19:07 - INFO - Application started
2025-07-07 11:19:07 - ERROR - Failed to load tabs
Traceback (most recent call last):
  File "C:\Users\int.nimeth\Desktop\codePuls_collector\app.py", line 56, in setup_tabs
    from tabs.code_repository_tab import setup_repositories_tab
  File "C:\Users\int.nimeth\Desktop\codePuls_collector\tabs\code_repository_tab.py", line 6, in <module>
    from controller.code_repository_controller import on_tab_changed,check_all_repositories,save_selected_repositories
  File "C:\Users\int.nimeth\Desktop\codePuls_collector\controller\code_repository_controller.py", line 14, in <module>
    from models.code_repository_model import fetch_code_repository_data
ImportError: cannot import name 'fetch_code_repository_data' from 'models.code_repository_model' (C:\Users\int.nimeth\Desktop\codePuls_collector\models\code_repository_model.py)
2025-07-07 11:19:07 - ERROR - Unhandled exception occurred
Traceback (most recent call last):
  File "C:\Users\int.nimeth\Desktop\codePuls_collector\app.py", line 56, in setup_tabs
    from tabs.code_repository_tab import setup_repositories_tab
  File "C:\Users\int.nimeth\Desktop\codePuls_collector\tabs\code_repository_tab.py", line 6, in <module>
    from controller.code_repository_controller import on_tab_changed,check_all_repositories,save_selected_repositories
  File "C:\Users\int.nimeth\Desktop\codePuls_collector\controller\code_repository_controller.py", line 14, in <module>
    from models.code_repository_model import fetch_code_repository_data
ImportError: cannot import name 'fetch_code_repository_data' from 'models.code_repository_model' (C:\Users\int.nimeth\Desktop\codePuls_collector\models\code_repository_model.py)

During handling of the above exception, another exception occurred:

Traceback (most recent call last):
  File "C:\Users\int.nimeth\Desktop\codePuls_collector\main.py", line 12, in main
    window = SourceProviderTool()
  File "C:\Users\int.nimeth\Desktop\codePuls_collector\app.py", line 16, in __init__
    self.init_ui()
    ~~~~~~~~~~~~^^
  File "C:\Users\int.nimeth\Desktop\codePuls_collector\app.py", line 41, in init_ui
    self.setup_tabs()
    ~~~~~~~~~~~~~~~^^
  File "C:\Users\int.nimeth\Desktop\codePuls_collector\app.py", line 70, in setup_tabs
    show_error_message(str(e))
    ~~~~~~~~~~~~~~~~~~^^^^^^^^
TypeError: show_error_message() missing 1 required positional argument: 'error'
2025-07-07 11:21:13 - INFO - Application started
2025-07-07 11:21:13 - ERROR - Failed to load tabs
Traceback (most recent call last):
  File "C:\Users\int.nimeth\Desktop\codePuls_collector\app.py", line 56, in setup_tabs
    from tabs.code_repository_tab import setup_repositories_tab
  File "C:\Users\int.nimeth\Desktop\codePuls_collector\tabs\code_repository_tab.py", line 6, in <module>
    from controller.code_repository_controller import on_tab_changed,check_all_repositories,save_selected_repositories
  File "C:\Users\int.nimeth\Desktop\codePuls_collector\controller\code_repository_controller.py", line 14, in <module>
    from models.code_repository_model import fetch_code_repository_data,save_code_repositories
ImportError: cannot import name 'fetch_code_repository_data' from 'models.code_repository_model' (C:\Users\int.nimeth\Desktop\codePuls_collector\models\code_repository_model.py)
2025-07-07 11:21:13 - ERROR - Unhandled exception occurred
Traceback (most recent call last):
  File "C:\Users\int.nimeth\Desktop\codePuls_collector\app.py", line 56, in setup_tabs
    from tabs.code_repository_tab import setup_repositories_tab
  File "C:\Users\int.nimeth\Desktop\codePuls_collector\tabs\code_repository_tab.py", line 6, in <module>
    from controller.code_repository_controller import on_tab_changed,check_all_repositories,save_selected_repositories
  File "C:\Users\int.nimeth\Desktop\codePuls_collector\controller\code_repository_controller.py", line 14, in <module>
    from models.code_repository_model import fetch_code_repository_data,save_code_repositories
ImportError: cannot import name 'fetch_code_repository_data' from 'models.code_repository_model' (C:\Users\int.nimeth\Desktop\codePuls_collector\models\code_repository_model.py)

During handling of the above exception, another exception occurred:

Traceback (most recent call last):
  File "C:\Users\int.nimeth\Desktop\codePuls_collector\main.py", line 12, in main
    window = SourceProviderTool()
  File "C:\Users\int.nimeth\Desktop\codePuls_collector\app.py", line 16, in __init__
    self.init_ui()
    ~~~~~~~~~~~~^^
  File "C:\Users\int.nimeth\Desktop\codePuls_collector\app.py", line 41, in init_ui
    self.setup_tabs()
    ~~~~~~~~~~~~~~~^^
  File "C:\Users\int.nimeth\Desktop\codePuls_collector\app.py", line 70, in setup_tabs
    show_error_message(str(e))
    ~~~~~~~~~~~~~~~~~~^^^^^^^^
TypeError: show_error_message() missing 1 required positional argument: 'error'
2025-07-07 11:23:04 - INFO - Application started
2025-07-07 11:23:05 - ERROR - Failed to load tabs
Traceback (most recent call last):
  File "C:\Users\int.nimeth\Desktop\codePuls_collector\app.py", line 57, in setup_tabs
    from tabs.pull_request_tab import setup_pull_request_tab
  File "C:\Users\int.nimeth\Desktop\codePuls_collector\tabs\pull_request_tab.py", line 5, in <module>
    from controller.pull_request_controller import fetch_and_save_new_pull_requests,fetch_last_pull_request,on_tab_changed
  File "C:\Users\int.nimeth\Desktop\codePuls_collector\controller\pull_request_controller.py", line 11, in <module>
    from controller.code_repository_controller import get_saved_repositories
ImportError: cannot import name 'get_saved_repositories' from 'controller.code_repository_controller' (C:\Users\int.nimeth\Desktop\codePuls_collector\controller\code_repository_controller.py)
2025-07-07 11:23:05 - ERROR - Unhandled exception occurred
Traceback (most recent call last):
  File "C:\Users\int.nimeth\Desktop\codePuls_collector\app.py", line 57, in setup_tabs
    from tabs.pull_request_tab import setup_pull_request_tab
  File "C:\Users\int.nimeth\Desktop\codePuls_collector\tabs\pull_request_tab.py", line 5, in <module>
    from controller.pull_request_controller import fetch_and_save_new_pull_requests,fetch_last_pull_request,on_tab_changed
  File "C:\Users\int.nimeth\Desktop\codePuls_collector\controller\pull_request_controller.py", line 11, in <module>
    from controller.code_repository_controller import get_saved_repositories
ImportError: cannot import name 'get_saved_repositories' from 'controller.code_repository_controller' (C:\Users\int.nimeth\Desktop\codePuls_collector\controller\code_repository_controller.py)

During handling of the above exception, another exception occurred:

Traceback (most recent call last):
  File "C:\Users\int.nimeth\Desktop\codePuls_collector\main.py", line 12, in main
    window = SourceProviderTool()
  File "C:\Users\int.nimeth\Desktop\codePuls_collector\app.py", line 16, in __init__
    self.init_ui()
    ~~~~~~~~~~~~^^
  File "C:\Users\int.nimeth\Desktop\codePuls_collector\app.py", line 41, in init_ui
    self.setup_tabs()
    ~~~~~~~~~~~~~~~^^
  File "C:\Users\int.nimeth\Desktop\codePuls_collector\app.py", line 70, in setup_tabs
    show_error_message(str(e))
    ~~~~~~~~~~~~~~~~~~^^^^^^^^
TypeError: show_error_message() missing 1 required positional argument: 'error'
2025-07-07 11:24:20 - INFO - Application started
2025-07-07 11:25:47 - INFO - Application started
2025-07-07 11:26:49 - INFO - Application started
2025-07-07 11:27:31 - INFO - Application started
2025-07-07 11:28:38 - INFO - Application started
2025-07-07 11:31:57 - INFO - Application started
2025-07-07 11:33:05 - INFO - Application started
2025-07-07 11:49:33 - INFO - Application started
2025-07-07 11:50:39 - INFO - Application started
2025-07-07 11:53:56 - INFO - Application started
2025-07-07 11:53:56 - ERROR - Failed to load tabs
Traceback (most recent call last):
  File "C:\Users\int.nimeth\Desktop\codePuls_collector\app.py", line 56, in setup_tabs
    from tabs.code_repository_tab import setup_repositories_tab
  File "C:\Users\int.nimeth\Desktop\codePuls_collector\tabs\code_repository_tab.py", line 6, in <module>
    from controller.code_repository_controller import on_tab_changed,check_all_repositories,save_selected_repositories
  File "C:\Users\int.nimeth\Desktop\codePuls_collector\controller\code_repository_controller.py", line 7, in <module>
    from services.backend.get_repository_data_service import get_repository_data_service
ModuleNotFoundError: No module named 'services.backend.get_repository_data_service'
2025-07-07 11:53:56 - ERROR - Unhandled exception occurred
Traceback (most recent call last):
  File "C:\Users\int.nimeth\Desktop\codePuls_collector\app.py", line 56, in setup_tabs
    from tabs.code_repository_tab import setup_repositories_tab
  File "C:\Users\int.nimeth\Desktop\codePuls_collector\tabs\code_repository_tab.py", line 6, in <module>
    from controller.code_repository_controller import on_tab_changed,check_all_repositories,save_selected_repositories
  File "C:\Users\int.nimeth\Desktop\codePuls_collector\controller\code_repository_controller.py", line 7, in <module>
    from services.backend.get_repository_data_service import get_repository_data_service
ModuleNotFoundError: No module named 'services.backend.get_repository_data_service'

During handling of the above exception, another exception occurred:

Traceback (most recent call last):
  File "C:\Users\int.nimeth\Desktop\codePuls_collector\main.py", line 12, in main
    window = SourceProviderTool()
  File "C:\Users\int.nimeth\Desktop\codePuls_collector\app.py", line 16, in __init__
    self.init_ui()
    ~~~~~~~~~~~~^^
  File "C:\Users\int.nimeth\Desktop\codePuls_collector\app.py", line 41, in init_ui
    self.setup_tabs()
    ~~~~~~~~~~~~~~~^^
  File "C:\Users\int.nimeth\Desktop\codePuls_collector\app.py", line 70, in setup_tabs
    show_error_message(str(e))
    ~~~~~~~~~~~~~~~~~~^^^^^^^^
TypeError: show_error_message() missing 1 required positional argument: 'error'
2025-07-07 11:54:52 - INFO - Application started
2025-07-07 11:56:26 - INFO - Application started
2025-07-07 12:19:53 - INFO - Application started
2025-07-07 12:20:52 - INFO - Application started
2025-07-07 12:20:52 - ERROR - Failed to load tabs
Traceback (most recent call last):
  File "C:\Users\int.nimeth\Desktop\codePuls_collector\app.py", line 56, in setup_tabs
    from tabs.code_repository_tab import setup_repositories_tab
  File "C:\Users\int.nimeth\Desktop\codePuls_collector\tabs\code_repository_tab.py", line 6, in <module>
    from controller.code_repository_controller import on_tab_changed,check_all_repositories,save_selected_repositories
  File "C:\Users\int.nimeth\Desktop\codePuls_collector\controller\code_repository_controller.py", line 11, in <module>
    from models.coderepository_model import fetch_code_repository_data
ModuleNotFoundError: No module named 'models.coderepository_model'
2025-07-07 12:20:52 - ERROR - Unhandled exception occurred
Traceback (most recent call last):
  File "C:\Users\int.nimeth\Desktop\codePuls_collector\app.py", line 56, in setup_tabs
    from tabs.code_repository_tab import setup_repositories_tab
  File "C:\Users\int.nimeth\Desktop\codePuls_collector\tabs\code_repository_tab.py", line 6, in <module>
    from controller.code_repository_controller import on_tab_changed,check_all_repositories,save_selected_repositories
  File "C:\Users\int.nimeth\Desktop\codePuls_collector\controller\code_repository_controller.py", line 11, in <module>
    from models.coderepository_model import fetch_code_repository_data
ModuleNotFoundError: No module named 'models.coderepository_model'

During handling of the above exception, another exception occurred:

Traceback (most recent call last):
  File "C:\Users\int.nimeth\Desktop\codePuls_collector\main.py", line 12, in main
    window = SourceProviderTool()
  File "C:\Users\int.nimeth\Desktop\codePuls_collector\app.py", line 16, in __init__
    self.init_ui()
    ~~~~~~~~~~~~^^
  File "C:\Users\int.nimeth\Desktop\codePuls_collector\app.py", line 41, in init_ui
    self.setup_tabs()
    ~~~~~~~~~~~~~~~^^
  File "C:\Users\int.nimeth\Desktop\codePuls_collector\app.py", line 70, in setup_tabs
    show_error_message(str(e))
    ~~~~~~~~~~~~~~~~~~^^^^^^^^
TypeError: show_error_message() missing 1 required positional argument: 'error'
2025-07-07 12:21:12 - INFO - Application started
2025-07-07 12:57:36 - INFO - Application started
2025-07-07 13:04:36 - INFO - Application started
2025-07-07 13:06:01 - INFO - Application started
2025-07-07 13:08:14 - INFO - Application started
2025-07-07 13:10:38 - INFO - Application started
2025-07-07 13:11:15 - INFO - Application started
2025-07-07 13:11:57 - INFO - Application started
2025-07-07 13:13:03 - INFO - Application started
2025-07-07 13:21:54 - INFO - Application started
2025-07-07 13:22:40 - INFO - Application started
2025-07-07 13:23:33 - INFO - Application started
2025-07-07 13:33:44 - INFO - Application started
2025-07-07 13:33:44 - ERROR - Failed to load tabs
Traceback (most recent call last):
  File "C:\Users\int.nimeth\Desktop\codePuls_collector\app.py", line 57, in setup_tabs
    from tabs.pull_request_tab import setup_pull_request_tab
  File "C:\Users\int.nimeth\Desktop\codePuls_collector\tabs\pull_request_tab.py", line 5, in <module>
    from controller.pull_request_controller import fetch_and_save_new_pull_requests,fetch_last_pull_request,on_tab_changed
  File "C:\Users\int.nimeth\Desktop\codePuls_collector\controller\pull_request_controller.py", line 10, in <module>
    from models.pull_request_model import fetch_pull_request_data,fetch_last_pr_data
  File "C:\Users\int.nimeth\Desktop\codePuls_collector\models\pull_request_model.py", line 28
    if not pr_payload:
IndentationError: unexpected indent
2025-07-07 13:33:44 - ERROR - Unhandled exception occurred
Traceback (most recent call last):
  File "C:\Users\int.nimeth\Desktop\codePuls_collector\app.py", line 57, in setup_tabs
    from tabs.pull_request_tab import setup_pull_request_tab
  File "C:\Users\int.nimeth\Desktop\codePuls_collector\tabs\pull_request_tab.py", line 5, in <module>
    from controller.pull_request_controller import fetch_and_save_new_pull_requests,fetch_last_pull_request,on_tab_changed
  File "C:\Users\int.nimeth\Desktop\codePuls_collector\controller\pull_request_controller.py", line 10, in <module>
    from models.pull_request_model import fetch_pull_request_data,fetch_last_pr_data
  File "C:\Users\int.nimeth\Desktop\codePuls_collector\models\pull_request_model.py", line 28
    if not pr_payload:
IndentationError: unexpected indent

During handling of the above exception, another exception occurred:

Traceback (most recent call last):
  File "C:\Users\int.nimeth\Desktop\codePuls_collector\main.py", line 12, in main
    window = SourceProviderTool()
  File "C:\Users\int.nimeth\Desktop\codePuls_collector\app.py", line 16, in __init__
    self.init_ui()
    ~~~~~~~~~~~~^^
  File "C:\Users\int.nimeth\Desktop\codePuls_collector\app.py", line 41, in init_ui
    self.setup_tabs()
    ~~~~~~~~~~~~~~~^^
  File "C:\Users\int.nimeth\Desktop\codePuls_collector\app.py", line 70, in setup_tabs
    show_error_message(str(e))
    ~~~~~~~~~~~~~~~~~~^^^^^^^^
TypeError: show_error_message() missing 1 required positional argument: 'error'
2025-07-07 13:34:37 - INFO - Application started
2025-07-07 13:38:53 - INFO - Application started
2025-07-07 13:40:02 - INFO - Application started
2025-07-07 13:41:40 - INFO - Application started
2025-07-07 13:43:30 - INFO - Application started
2025-07-07 13:45:13 - INFO - Application started
2025-07-07 13:46:28 - INFO - Application started
2025-07-07 14:17:04 - INFO - Application started
2025-07-07 14:17:05 - ERROR - Failed to load tabs
Traceback (most recent call last):
  File "C:\Users\int.nimeth\Desktop\codePuls_collector\app.py", line 55, in setup_tabs
    from tabs.team_member_tab import setup_team_member_tab
  File "C:\Users\int.nimeth\Desktop\codePuls_collector\tabs\team_member_tab.py", line 6, in <module>
    from controller.team_member_controller import on_tab_changed,save_selected_team_members,display_team_members,check_all_users
  File "C:\Users\int.nimeth\Desktop\codePuls_collector\controller\team_member_controller.py", line 12, in <module>
    from model.team_member_model import save_team_members,fetch_team_member_data
ModuleNotFoundError: No module named 'model'
2025-07-07 14:17:05 - ERROR - Unhandled exception occurred
Traceback (most recent call last):
  File "C:\Users\int.nimeth\Desktop\codePuls_collector\app.py", line 55, in setup_tabs
    from tabs.team_member_tab import setup_team_member_tab
  File "C:\Users\int.nimeth\Desktop\codePuls_collector\tabs\team_member_tab.py", line 6, in <module>
    from controller.team_member_controller import on_tab_changed,save_selected_team_members,display_team_members,check_all_users
  File "C:\Users\int.nimeth\Desktop\codePuls_collector\controller\team_member_controller.py", line 12, in <module>
    from model.team_member_model import save_team_members,fetch_team_member_data
ModuleNotFoundError: No module named 'model'

During handling of the above exception, another exception occurred:

Traceback (most recent call last):
  File "C:\Users\int.nimeth\Desktop\codePuls_collector\main.py", line 12, in main
    window = SourceProviderTool()
  File "C:\Users\int.nimeth\Desktop\codePuls_collector\app.py", line 16, in __init__
    self.init_ui()
    ~~~~~~~~~~~~^^
  File "C:\Users\int.nimeth\Desktop\codePuls_collector\app.py", line 41, in init_ui
    self.setup_tabs()
    ~~~~~~~~~~~~~~~^^
  File "C:\Users\int.nimeth\Desktop\codePuls_collector\app.py", line 70, in setup_tabs
    show_error_message(str(e))
    ~~~~~~~~~~~~~~~~~~^^^^^^^^
TypeError: show_error_message() missing 1 required positional argument: 'error'
2025-07-07 14:17:31 - INFO - Application started
2025-07-07 14:21:11 - INFO - Application started
2025-07-07 14:22:47 - INFO - Application started
2025-07-07 14:25:06 - INFO - Application started
2025-07-07 14:26:04 - INFO - Application started
2025-07-07 14:26:05 - ERROR - Failed to load tabs
Traceback (most recent call last):
  File "C:\Users\int.nimeth\Desktop\codePuls_collector\app.py", line 55, in setup_tabs
    from tabs.team_member_tab import setup_team_member_tab
  File "C:\Users\int.nimeth\Desktop\codePuls_collector\tabs\team_member_tab.py", line 6, in <module>
    from controller.team_member_controller import on_tab_changed,save_selected_team_members,display_team_members,check_all_users
  File "C:\Users\int.nimeth\Desktop\codePuls_collector\controller\team_member_controller.py", line 14, in <module>
    from models.team_member_model.py import fetch_team_member_data
ModuleNotFoundError: No module named 'models.team_member_model.py'; 'models.team_member_model' is not a package
2025-07-07 14:26:05 - ERROR - Unhandled exception occurred
Traceback (most recent call last):
  File "C:\Users\int.nimeth\Desktop\codePuls_collector\app.py", line 55, in setup_tabs
    from tabs.team_member_tab import setup_team_member_tab
  File "C:\Users\int.nimeth\Desktop\codePuls_collector\tabs\team_member_tab.py", line 6, in <module>
    from controller.team_member_controller import on_tab_changed,save_selected_team_members,display_team_members,check_all_users
  File "C:\Users\int.nimeth\Desktop\codePuls_collector\controller\team_member_controller.py", line 14, in <module>
    from models.team_member_model.py import fetch_team_member_data
ModuleNotFoundError: No module named 'models.team_member_model.py'; 'models.team_member_model' is not a package

During handling of the above exception, another exception occurred:

Traceback (most recent call last):
  File "C:\Users\int.nimeth\Desktop\codePuls_collector\main.py", line 12, in main
    window = SourceProviderTool()
  File "C:\Users\int.nimeth\Desktop\codePuls_collector\app.py", line 16, in __init__
    self.init_ui()
    ~~~~~~~~~~~~^^
  File "C:\Users\int.nimeth\Desktop\codePuls_collector\app.py", line 41, in init_ui
    self.setup_tabs()
    ~~~~~~~~~~~~~~~^^
  File "C:\Users\int.nimeth\Desktop\codePuls_collector\app.py", line 70, in setup_tabs
    show_error_message(str(e))
    ~~~~~~~~~~~~~~~~~~^^^^^^^^
TypeError: show_error_message() missing 1 required positional argument: 'error'
2025-07-07 14:26:35 - INFO - Application started
2025-07-07 14:27:41 - INFO - Application started
2025-07-07 14:28:55 - INFO - Application started
2025-07-07 14:30:16 - INFO - Application started
2025-07-07 14:33:12 - INFO - Application started
2025-07-07 14:34:01 - INFO - Application started
2025-07-07 14:35:11 - INFO - Application started
2025-07-07 14:42:49 - INFO - Application started
2025-07-07 14:42:49 - ERROR - Failed to load tabs
Traceback (most recent call last):
  File "C:\Users\int.nimeth\Desktop\codePuls_collector\app.py", line 57, in setup_tabs
    from tabs.pull_request_tab import setup_pull_request_tab
  File "C:\Users\int.nimeth\Desktop\codePuls_collector\tabs\pull_request_tab.py", line 5, in <module>
    from controller.pull_request_presenter import fetch_and_save_new_pull_requests,fetch_last_pull_request,on_tab_changed
ModuleNotFoundError: No module named 'controller.pull_request_presenter'
2025-07-07 14:42:49 - ERROR - Unhandled exception occurred
Traceback (most recent call last):
  File "C:\Users\int.nimeth\Desktop\codePuls_collector\app.py", line 57, in setup_tabs
    from tabs.pull_request_tab import setup_pull_request_tab
  File "C:\Users\int.nimeth\Desktop\codePuls_collector\tabs\pull_request_tab.py", line 5, in <module>
    from controller.pull_request_presenter import fetch_and_save_new_pull_requests,fetch_last_pull_request,on_tab_changed
ModuleNotFoundError: No module named 'controller.pull_request_presenter'

During handling of the above exception, another exception occurred:

Traceback (most recent call last):
  File "C:\Users\int.nimeth\Desktop\codePuls_collector\main.py", line 12, in main
    window = SourceProviderTool()
  File "C:\Users\int.nimeth\Desktop\codePuls_collector\app.py", line 16, in __init__
    self.init_ui()
    ~~~~~~~~~~~~^^
  File "C:\Users\int.nimeth\Desktop\codePuls_collector\app.py", line 41, in init_ui
    self.setup_tabs()
    ~~~~~~~~~~~~~~~^^
  File "C:\Users\int.nimeth\Desktop\codePuls_collector\app.py", line 70, in setup_tabs
    show_error_message(str(e))
    ~~~~~~~~~~~~~~~~~~^^^^^^^^
TypeError: show_error_message() missing 1 required positional argument: 'error'
2025-07-07 14:43:48 - INFO - Application started
2025-07-07 15:00:00 - INFO - Application started
2025-07-07 15:02:44 - INFO - Application started
2025-07-07 15:10:02 - INFO - Application started
2025-07-07 15:11:04 - INFO - Application started
2025-07-07 15:12:03 - INFO - Application started
2025-07-07 15:13:35 - INFO - Application started
2025-07-07 15:25:29 - INFO - Application started
2025-07-07 15:27:31 - INFO - Application started
2025-07-07 15:28:12 - INFO - Application started
2025-07-08 09:17:34 - INFO - Application started
2025-07-08 09:19:13 - INFO - Application started
2025-07-08 09:22:00 - INFO - Application started
2025-07-08 09:54:41 - INFO - Application started
2025-07-08 09:56:03 - INFO - Application started
2025-07-08 09:56:54 - INFO - Application started
2025-07-08 10:06:03 - INFO - Application started
2025-07-08 10:11:24 - INFO - Application started
2025-07-08 10:12:54 - INFO - Application started
2025-07-08 10:38:18 - INFO - Application started
2025-07-08 10:39:38 - INFO - Application started
2025-07-08 10:41:08 - INFO - Application started
2025-07-08 11:22:47 - INFO - Application started
2025-07-08 11:22:47 - ERROR - Failed to load tabs
Traceback (most recent call last):
  File "C:\Users\int.nimeth\Desktop\codePuls_collector\app.py", line 54, in setup_tabs
    from tabs.user_tab import setup_user_tab
  File "C:\Users\int.nimeth\Desktop\codePuls_collector\tabs\user_tab.py", line 6, in <module>
    from presenters.common.on_tab_change_presenter import on_tab_changed
  File "C:\Users\int.nimeth\Desktop\codePuls_collector\presenters\common\on_tab_change_presenter.py", line 1, in <module>
    from tab_changr_handlers import TAB_HANDLERS
ModuleNotFoundError: No module named 'tab_changr_handlers'
2025-07-08 11:22:47 - ERROR - Unhandled exception occurred
Traceback (most recent call last):
  File "C:\Users\int.nimeth\Desktop\codePuls_collector\app.py", line 54, in setup_tabs
    from tabs.user_tab import setup_user_tab
  File "C:\Users\int.nimeth\Desktop\codePuls_collector\tabs\user_tab.py", line 6, in <module>
    from presenters.common.on_tab_change_presenter import on_tab_changed
  File "C:\Users\int.nimeth\Desktop\codePuls_collector\presenters\common\on_tab_change_presenter.py", line 1, in <module>
    from tab_changr_handlers import TAB_HANDLERS
ModuleNotFoundError: No module named 'tab_changr_handlers'

During handling of the above exception, another exception occurred:

Traceback (most recent call last):
  File "C:\Users\int.nimeth\Desktop\codePuls_collector\main.py", line 12, in main
    window = SourceProviderTool()
  File "C:\Users\int.nimeth\Desktop\codePuls_collector\app.py", line 16, in __init__
    self.init_ui()
    ~~~~~~~~~~~~^^
  File "C:\Users\int.nimeth\Desktop\codePuls_collector\app.py", line 42, in init_ui
    self.setup_tabs()
    ~~~~~~~~~~~~~~~^^
  File "C:\Users\int.nimeth\Desktop\codePuls_collector\app.py", line 71, in setup_tabs
    show_error_message(str(e))
    ~~~~~~~~~~~~~~~~~~^^^^^^^^
TypeError: show_error_message() missing 1 required positional argument: 'error'
2025-07-08 11:23:15 - INFO - Application started
2025-07-08 11:23:15 - ERROR - Failed to load tabs
Traceback (most recent call last):
  File "C:\Users\int.nimeth\Desktop\codePuls_collector\app.py", line 54, in setup_tabs
    from tabs.user_tab import setup_user_tab
  File "C:\Users\int.nimeth\Desktop\codePuls_collector\tabs\user_tab.py", line 6, in <module>
    from presenters.common.on_tab_change_presenter import on_tab_changed
  File "C:\Users\int.nimeth\Desktop\codePuls_collector\presenters\common\on_tab_change_presenter.py", line 1, in <module>
    from tab_change_handlers import TAB_HANDLERS
ModuleNotFoundError: No module named 'tab_change_handlers'
2025-07-08 11:23:15 - ERROR - Unhandled exception occurred
Traceback (most recent call last):
  File "C:\Users\int.nimeth\Desktop\codePuls_collector\app.py", line 54, in setup_tabs
    from tabs.user_tab import setup_user_tab
  File "C:\Users\int.nimeth\Desktop\codePuls_collector\tabs\user_tab.py", line 6, in <module>
    from presenters.common.on_tab_change_presenter import on_tab_changed
  File "C:\Users\int.nimeth\Desktop\codePuls_collector\presenters\common\on_tab_change_presenter.py", line 1, in <module>
    from tab_change_handlers import TAB_HANDLERS
ModuleNotFoundError: No module named 'tab_change_handlers'

During handling of the above exception, another exception occurred:

Traceback (most recent call last):
  File "C:\Users\int.nimeth\Desktop\codePuls_collector\main.py", line 12, in main
    window = SourceProviderTool()
  File "C:\Users\int.nimeth\Desktop\codePuls_collector\app.py", line 16, in __init__
    self.init_ui()
    ~~~~~~~~~~~~^^
  File "C:\Users\int.nimeth\Desktop\codePuls_collector\app.py", line 42, in init_ui
    self.setup_tabs()
    ~~~~~~~~~~~~~~~^^
  File "C:\Users\int.nimeth\Desktop\codePuls_collector\app.py", line 71, in setup_tabs
    show_error_message(str(e))
    ~~~~~~~~~~~~~~~~~~^^^^^^^^
TypeError: show_error_message() missing 1 required positional argument: 'error'
2025-07-08 11:23:54 - INFO - Application started
2025-07-08 11:23:54 - ERROR - Failed to load tabs
Traceback (most recent call last):
  File "C:\Users\int.nimeth\Desktop\codePuls_collector\app.py", line 54, in setup_tabs
    from tabs.user_tab import setup_user_tab
  File "C:\Users\int.nimeth\Desktop\codePuls_collector\tabs\user_tab.py", line 6, in <module>
    from presenters.common.on_tab_change_presenter import on_tab_changed
  File "C:\Users\int.nimeth\Desktop\codePuls_collector\presenters\common\on_tab_change_presenter.py", line 1, in <module>
    from common.tab_change_handlers import TAB_HANDLERS
ModuleNotFoundError: No module named 'common'
2025-07-08 11:23:54 - ERROR - Unhandled exception occurred
Traceback (most recent call last):
  File "C:\Users\int.nimeth\Desktop\codePuls_collector\app.py", line 54, in setup_tabs
    from tabs.user_tab import setup_user_tab
  File "C:\Users\int.nimeth\Desktop\codePuls_collector\tabs\user_tab.py", line 6, in <module>
    from presenters.common.on_tab_change_presenter import on_tab_changed
  File "C:\Users\int.nimeth\Desktop\codePuls_collector\presenters\common\on_tab_change_presenter.py", line 1, in <module>
    from common.tab_change_handlers import TAB_HANDLERS
ModuleNotFoundError: No module named 'common'

During handling of the above exception, another exception occurred:

Traceback (most recent call last):
  File "C:\Users\int.nimeth\Desktop\codePuls_collector\main.py", line 12, in main
    window = SourceProviderTool()
  File "C:\Users\int.nimeth\Desktop\codePuls_collector\app.py", line 16, in __init__
    self.init_ui()
    ~~~~~~~~~~~~^^
  File "C:\Users\int.nimeth\Desktop\codePuls_collector\app.py", line 42, in init_ui
    self.setup_tabs()
    ~~~~~~~~~~~~~~~^^
  File "C:\Users\int.nimeth\Desktop\codePuls_collector\app.py", line 71, in setup_tabs
    show_error_message(str(e))
    ~~~~~~~~~~~~~~~~~~^^^^^^^^
TypeError: show_error_message() missing 1 required positional argument: 'error'
2025-07-08 11:24:07 - INFO - Application started
2025-07-08 11:24:07 - ERROR - Failed to load tabs
Traceback (most recent call last):
  File "C:\Users\int.nimeth\Desktop\codePuls_collector\app.py", line 54, in setup_tabs
    from tabs.user_tab import setup_user_tab
  File "C:\Users\int.nimeth\Desktop\codePuls_collector\tabs\user_tab.py", line 6, in <module>
    from presenters.common.on_tab_change_presenter import on_tab_changed
  File "C:\Users\int.nimeth\Desktop\codePuls_collector\presenters\common\on_tab_change_presenter.py", line 1, in <module>
    from presenters.common.tab_change_handlers import TAB_HANDLERS
  File "C:\Users\int.nimeth\Desktop\codePuls_collector\presenters\common\tab_change_handlers.py", line 1, in <module>
    from presenters.user_presenter import load_user_data
ImportError: cannot import name 'load_user_data' from 'presenters.user_presenter' (C:\Users\int.nimeth\Desktop\codePuls_collector\presenters\user_presenter.py)
2025-07-08 11:24:07 - ERROR - Unhandled exception occurred
Traceback (most recent call last):
  File "C:\Users\int.nimeth\Desktop\codePuls_collector\app.py", line 54, in setup_tabs
    from tabs.user_tab import setup_user_tab
  File "C:\Users\int.nimeth\Desktop\codePuls_collector\tabs\user_tab.py", line 6, in <module>
    from presenters.common.on_tab_change_presenter import on_tab_changed
  File "C:\Users\int.nimeth\Desktop\codePuls_collector\presenters\common\on_tab_change_presenter.py", line 1, in <module>
    from presenters.common.tab_change_handlers import TAB_HANDLERS
  File "C:\Users\int.nimeth\Desktop\codePuls_collector\presenters\common\tab_change_handlers.py", line 1, in <module>
    from presenters.user_presenter import load_user_data
ImportError: cannot import name 'load_user_data' from 'presenters.user_presenter' (C:\Users\int.nimeth\Desktop\codePuls_collector\presenters\user_presenter.py)

During handling of the above exception, another exception occurred:

Traceback (most recent call last):
  File "C:\Users\int.nimeth\Desktop\codePuls_collector\main.py", line 12, in main
    window = SourceProviderTool()
  File "C:\Users\int.nimeth\Desktop\codePuls_collector\app.py", line 16, in __init__
    self.init_ui()
    ~~~~~~~~~~~~^^
  File "C:\Users\int.nimeth\Desktop\codePuls_collector\app.py", line 42, in init_ui
    self.setup_tabs()
    ~~~~~~~~~~~~~~~^^
  File "C:\Users\int.nimeth\Desktop\codePuls_collector\app.py", line 71, in setup_tabs
    show_error_message(str(e))
    ~~~~~~~~~~~~~~~~~~^^^^^^^^
TypeError: show_error_message() missing 1 required positional argument: 'error'
2025-07-08 11:24:59 - INFO - Application started
2025-07-08 11:24:59 - ERROR - Failed to load tabs
Traceback (most recent call last):
  File "C:\Users\int.nimeth\Desktop\codePuls_collector\app.py", line 54, in setup_tabs
    from tabs.user_tab import setup_user_tab
  File "C:\Users\int.nimeth\Desktop\codePuls_collector\tabs\user_tab.py", line 6, in <module>
    from presenters.common.on_tab_change_presenter import on_tab_changed
  File "C:\Users\int.nimeth\Desktop\codePuls_collector\presenters\common\on_tab_change_presenter.py", line 1, in <module>
    from presenters.common.tab_change_handlers import TAB_HANDLERS
ImportError: cannot import name 'TAB_HANDLERS' from 'presenters.common.tab_change_handlers' (C:\Users\int.nimeth\Desktop\codePuls_collector\presenters\common\tab_change_handlers.py)
2025-07-08 11:24:59 - ERROR - Unhandled exception occurred
Traceback (most recent call last):
  File "C:\Users\int.nimeth\Desktop\codePuls_collector\app.py", line 54, in setup_tabs
    from tabs.user_tab import setup_user_tab
  File "C:\Users\int.nimeth\Desktop\codePuls_collector\tabs\user_tab.py", line 6, in <module>
    from presenters.common.on_tab_change_presenter import on_tab_changed
  File "C:\Users\int.nimeth\Desktop\codePuls_collector\presenters\common\on_tab_change_presenter.py", line 1, in <module>
    from presenters.common.tab_change_handlers import TAB_HANDLERS
ImportError: cannot import name 'TAB_HANDLERS' from 'presenters.common.tab_change_handlers' (C:\Users\int.nimeth\Desktop\codePuls_collector\presenters\common\tab_change_handlers.py)

During handling of the above exception, another exception occurred:

Traceback (most recent call last):
  File "C:\Users\int.nimeth\Desktop\codePuls_collector\main.py", line 12, in main
    window = SourceProviderTool()
  File "C:\Users\int.nimeth\Desktop\codePuls_collector\app.py", line 16, in __init__
    self.init_ui()
    ~~~~~~~~~~~~^^
  File "C:\Users\int.nimeth\Desktop\codePuls_collector\app.py", line 42, in init_ui
    self.setup_tabs()
    ~~~~~~~~~~~~~~~^^
  File "C:\Users\int.nimeth\Desktop\codePuls_collector\app.py", line 71, in setup_tabs
    show_error_message(str(e))
    ~~~~~~~~~~~~~~~~~~^^^^^^^^
TypeError: show_error_message() missing 1 required positional argument: 'error'
2025-07-08 11:25:35 - INFO - Application started
2025-07-08 11:27:14 - INFO - Application started
2025-07-08 11:33:37 - INFO - Application started
2025-07-08 11:51:01 - INFO - Application started
2025-07-08 14:19:08 - INFO - Application started
2025-07-08 14:21:37 - INFO - Application started
2025-07-09 16:40:55 - ERROR - Network error occurred during API request
Traceback (most recent call last):
  File "C:\Users\int.nimeth\AppData\Local\Programs\Python\Python313\Lib\site-packages\urllib3\connection.py", line 198, in _new_conn
    sock = connection.create_connection(
        (self._dns_host, self.port),
    ...<2 lines>...
        socket_options=self.socket_options,
    )
  File "C:\Users\int.nimeth\AppData\Local\Programs\Python\Python313\Lib\site-packages\urllib3\util\connection.py", line 85, in create_connection
    raise err
  File "C:\Users\int.nimeth\AppData\Local\Programs\Python\Python313\Lib\site-packages\urllib3\util\connection.py", line 73, in create_connection
    sock.connect(sa)
    ~~~~~~~~~~~~^^^^
ConnectionRefusedError: [WinError 10061] No connection could be made because the target machine actively refused it

The above exception was the direct cause of the following exception:

Traceback (most recent call last):
  File "C:\Users\int.nimeth\AppData\Local\Programs\Python\Python313\Lib\site-packages\urllib3\connectionpool.py", line 787, in urlopen
    response = self._make_request(
        conn,
    ...<10 lines>...
        **response_kw,
    )
  File "C:\Users\int.nimeth\AppData\Local\Programs\Python\Python313\Lib\site-packages\urllib3\connectionpool.py", line 493, in _make_request
    conn.request(
    ~~~~~~~~~~~~^
        method,
        ^^^^^^^
    ...<6 lines>...
        enforce_content_length=enforce_content_length,
        ^^^^^^^^^^^^^^^^^^^^^^^^^^^^^^^^^^^^^^^^^^^^^^
    )
    ^
  File "C:\Users\int.nimeth\AppData\Local\Programs\Python\Python313\Lib\site-packages\urllib3\connection.py", line 445, in request
    self.endheaders()
    ~~~~~~~~~~~~~~~^^
  File "C:\Users\int.nimeth\AppData\Local\Programs\Python\Python313\Lib\http\client.py", line 1333, in endheaders
    self._send_output(message_body, encode_chunked=encode_chunked)
    ~~~~~~~~~~~~~~~~~^^^^^^^^^^^^^^^^^^^^^^^^^^^^^^^^^^^^^^^^^^^^^
  File "C:\Users\int.nimeth\AppData\Local\Programs\Python\Python313\Lib\http\client.py", line 1093, in _send_output
    self.send(msg)
    ~~~~~~~~~^^^^^
  File "C:\Users\int.nimeth\AppData\Local\Programs\Python\Python313\Lib\http\client.py", line 1037, in send
    self.connect()
    ~~~~~~~~~~~~^^
  File "C:\Users\int.nimeth\AppData\Local\Programs\Python\Python313\Lib\site-packages\urllib3\connection.py", line 276, in connect
    self.sock = self._new_conn()
                ~~~~~~~~~~~~~~^^
  File "C:\Users\int.nimeth\AppData\Local\Programs\Python\Python313\Lib\site-packages\urllib3\connection.py", line 213, in _new_conn
    raise NewConnectionError(
        self, f"Failed to establish a new connection: {e}"
    ) from e
urllib3.exceptions.NewConnectionError: <urllib3.connection.HTTPConnection object at 0x0000024EB049E510>: Failed to establish a new connection: [WinError 10061] No connection could be made because the target machine actively refused it

The above exception was the direct cause of the following exception:

Traceback (most recent call last):
  File "C:\Users\int.nimeth\AppData\Local\Programs\Python\Python313\Lib\site-packages\requests\adapters.py", line 667, in send
    resp = conn.urlopen(
        method=request.method,
    ...<9 lines>...
        chunked=chunked,
    )
  File "C:\Users\int.nimeth\AppData\Local\Programs\Python\Python313\Lib\site-packages\urllib3\connectionpool.py", line 841, in urlopen
    retries = retries.increment(
        method, url, error=new_e, _pool=self, _stacktrace=sys.exc_info()[2]
    )
  File "C:\Users\int.nimeth\AppData\Local\Programs\Python\Python313\Lib\site-packages\urllib3\util\retry.py", line 519, in increment
    raise MaxRetryError(_pool, url, reason) from reason  # type: ignore[arg-type]
    ^^^^^^^^^^^^^^^^^^^^^^^^^^^^^^^^^^^^^^^^^^^^^^^^^^^
urllib3.exceptions.MaxRetryError: HTTPConnectionPool(host='localhost', port=5113): Max retries exceeded with url: /api/project (Caused by NewConnectionError('<urllib3.connection.HTTPConnection object at 0x0000024EB049E510>: Failed to establish a new connection: [WinError 10061] No connection could be made because the target machine actively refused it'))

During handling of the above exception, another exception occurred:

Traceback (most recent call last):
  File "C:\Users\int.nimeth\Desktop\codePuls_collector\services\backend\save_organization_data_service.py", line 9, in save_organization_data_service
    response = requests.post(
        USER_API["create_project"],
    ...<2 lines>...
        timeout=10
    )
  File "C:\Users\int.nimeth\AppData\Local\Programs\Python\Python313\Lib\site-packages\requests\api.py", line 115, in post
    return request("post", url, data=data, json=json, **kwargs)
  File "C:\Users\int.nimeth\AppData\Local\Programs\Python\Python313\Lib\site-packages\requests\api.py", line 59, in request
    return session.request(method=method, url=url, **kwargs)
           ~~~~~~~~~~~~~~~^^^^^^^^^^^^^^^^^^^^^^^^^^^^^^^^^^
  File "C:\Users\int.nimeth\AppData\Local\Programs\Python\Python313\Lib\site-packages\requests\sessions.py", line 589, in request
    resp = self.send(prep, **send_kwargs)
  File "C:\Users\int.nimeth\AppData\Local\Programs\Python\Python313\Lib\site-packages\requests\sessions.py", line 703, in send
    r = adapter.send(request, **kwargs)
  File "C:\Users\int.nimeth\AppData\Local\Programs\Python\Python313\Lib\site-packages\requests\adapters.py", line 700, in send
    raise ConnectionError(e, request=request)
requests.exceptions.ConnectionError: HTTPConnectionPool(host='localhost', port=5113): Max retries exceeded with url: /api/project (Caused by NewConnectionError('<urllib3.connection.HTTPConnection object at 0x0000024EB049E510>: Failed to establish a new connection: [WinError 10061] No connection could be made because the target machine actively refused it'))
2025-07-09 17:03:40 - ERROR - API Error: A database error occurred. Please try again later.
2025-07-09 17:03:53 - INFO - Application started
2025-07-11 09:47:12 - INFO - Application started
2025-07-11 09:50:43 - INFO - Application started
2025-07-11 09:51:08 - INFO - Application started
2025-07-11 09:53:22 - INFO - Application started
2025-07-11 09:54:14 - INFO - Application started
2025-07-11 09:55:41 - INFO - Application started
2025-07-11 09:56:54 - INFO - Application started
2025-07-11 09:59:26 - INFO - Application started
2025-07-11 10:00:21 - INFO - Application started
2025-07-11 10:13:53 - INFO - Application started
2025-07-11 10:17:05 - INFO - Application started
2025-07-11 10:20:07 - INFO - Application started
2025-07-11 10:26:23 - INFO - Application started
2025-07-11 10:46:54 - INFO - Application started
2025-07-11 10:50:42 - ERROR - API Error: An unexpected error occurred.
2025-07-11 10:51:18 - ERROR - API Error: An unexpected error occurred.
2025-07-14 09:20:50 - INFO - Application started
2025-07-14 09:23:12 - ERROR - Network error occurred during API request
Traceback (most recent call last):
  File "C:\Users\int.nimeth\AppData\Local\Programs\Python\Python313\Lib\site-packages\urllib3\connection.py", line 198, in _new_conn
    sock = connection.create_connection(
        (self._dns_host, self.port),
    ...<2 lines>...
        socket_options=self.socket_options,
    )
  File "C:\Users\int.nimeth\AppData\Local\Programs\Python\Python313\Lib\site-packages\urllib3\util\connection.py", line 85, in create_connection
    raise err
  File "C:\Users\int.nimeth\AppData\Local\Programs\Python\Python313\Lib\site-packages\urllib3\util\connection.py", line 73, in create_connection
    sock.connect(sa)
    ~~~~~~~~~~~~^^^^
ConnectionRefusedError: [WinError 10061] No connection could be made because the target machine actively refused it

The above exception was the direct cause of the following exception:

Traceback (most recent call last):
  File "C:\Users\int.nimeth\AppData\Local\Programs\Python\Python313\Lib\site-packages\urllib3\connectionpool.py", line 787, in urlopen
    response = self._make_request(
        conn,
    ...<10 lines>...
        **response_kw,
    )
  File "C:\Users\int.nimeth\AppData\Local\Programs\Python\Python313\Lib\site-packages\urllib3\connectionpool.py", line 493, in _make_request
    conn.request(
    ~~~~~~~~~~~~^
        method,
        ^^^^^^^
    ...<6 lines>...
        enforce_content_length=enforce_content_length,
        ^^^^^^^^^^^^^^^^^^^^^^^^^^^^^^^^^^^^^^^^^^^^^^
    )
    ^
  File "C:\Users\int.nimeth\AppData\Local\Programs\Python\Python313\Lib\site-packages\urllib3\connection.py", line 445, in request
    self.endheaders()
    ~~~~~~~~~~~~~~~^^
  File "C:\Users\int.nimeth\AppData\Local\Programs\Python\Python313\Lib\http\client.py", line 1333, in endheaders
    self._send_output(message_body, encode_chunked=encode_chunked)
    ~~~~~~~~~~~~~~~~~^^^^^^^^^^^^^^^^^^^^^^^^^^^^^^^^^^^^^^^^^^^^^
  File "C:\Users\int.nimeth\AppData\Local\Programs\Python\Python313\Lib\http\client.py", line 1093, in _send_output
    self.send(msg)
    ~~~~~~~~~^^^^^
  File "C:\Users\int.nimeth\AppData\Local\Programs\Python\Python313\Lib\http\client.py", line 1037, in send
    self.connect()
    ~~~~~~~~~~~~^^
  File "C:\Users\int.nimeth\AppData\Local\Programs\Python\Python313\Lib\site-packages\urllib3\connection.py", line 276, in connect
    self.sock = self._new_conn()
                ~~~~~~~~~~~~~~^^
  File "C:\Users\int.nimeth\AppData\Local\Programs\Python\Python313\Lib\site-packages\urllib3\connection.py", line 213, in _new_conn
    raise NewConnectionError(
        self, f"Failed to establish a new connection: {e}"
    ) from e
urllib3.exceptions.NewConnectionError: <urllib3.connection.HTTPConnection object at 0x000001E645D26660>: Failed to establish a new connection: [WinError 10061] No connection could be made because the target machine actively refused it

The above exception was the direct cause of the following exception:

Traceback (most recent call last):
  File "C:\Users\int.nimeth\AppData\Local\Programs\Python\Python313\Lib\site-packages\requests\adapters.py", line 667, in send
    resp = conn.urlopen(
        method=request.method,
    ...<9 lines>...
        chunked=chunked,
    )
  File "C:\Users\int.nimeth\AppData\Local\Programs\Python\Python313\Lib\site-packages\urllib3\connectionpool.py", line 841, in urlopen
    retries = retries.increment(
        method, url, error=new_e, _pool=self, _stacktrace=sys.exc_info()[2]
    )
  File "C:\Users\int.nimeth\AppData\Local\Programs\Python\Python313\Lib\site-packages\urllib3\util\retry.py", line 519, in increment
    raise MaxRetryError(_pool, url, reason) from reason  # type: ignore[arg-type]
    ^^^^^^^^^^^^^^^^^^^^^^^^^^^^^^^^^^^^^^^^^^^^^^^^^^^
urllib3.exceptions.MaxRetryError: HTTPConnectionPool(host='localhost', port=5113): Max retries exceeded with url: /api/project (Caused by NewConnectionError('<urllib3.connection.HTTPConnection object at 0x000001E645D26660>: Failed to establish a new connection: [WinError 10061] No connection could be made because the target machine actively refused it'))

During handling of the above exception, another exception occurred:

Traceback (most recent call last):
  File "C:\Users\int.nimeth\Desktop\codePuls_collector\services\backend\save_organization_data_service.py", line 9, in save_organization_data_service
    response = requests.post(
        USER_API["create_project"],
    ...<2 lines>...
        timeout=10
    )
  File "C:\Users\int.nimeth\AppData\Local\Programs\Python\Python313\Lib\site-packages\requests\api.py", line 115, in post
    return request("post", url, data=data, json=json, **kwargs)
  File "C:\Users\int.nimeth\AppData\Local\Programs\Python\Python313\Lib\site-packages\requests\api.py", line 59, in request
    return session.request(method=method, url=url, **kwargs)
           ~~~~~~~~~~~~~~~^^^^^^^^^^^^^^^^^^^^^^^^^^^^^^^^^^
  File "C:\Users\int.nimeth\AppData\Local\Programs\Python\Python313\Lib\site-packages\requests\sessions.py", line 589, in request
    resp = self.send(prep, **send_kwargs)
  File "C:\Users\int.nimeth\AppData\Local\Programs\Python\Python313\Lib\site-packages\requests\sessions.py", line 703, in send
    r = adapter.send(request, **kwargs)
  File "C:\Users\int.nimeth\AppData\Local\Programs\Python\Python313\Lib\site-packages\requests\adapters.py", line 700, in send
    raise ConnectionError(e, request=request)
requests.exceptions.ConnectionError: HTTPConnectionPool(host='localhost', port=5113): Max retries exceeded with url: /api/project (Caused by NewConnectionError('<urllib3.connection.HTTPConnection object at 0x000001E645D26660>: Failed to establish a new connection: [WinError 10061] No connection could be made because the target machine actively refused it'))
2025-07-14 09:23:39 - ERROR - Network error occurred during API request
Traceback (most recent call last):
  File "C:\Users\int.nimeth\AppData\Local\Programs\Python\Python313\Lib\site-packages\urllib3\connectionpool.py", line 534, in _make_request
    response = conn.getresponse()
  File "C:\Users\int.nimeth\AppData\Local\Programs\Python\Python313\Lib\site-packages\urllib3\connection.py", line 516, in getresponse
    httplib_response = super().getresponse()
  File "C:\Users\int.nimeth\AppData\Local\Programs\Python\Python313\Lib\http\client.py", line 1430, in getresponse
    response.begin()
    ~~~~~~~~~~~~~~^^
  File "C:\Users\int.nimeth\AppData\Local\Programs\Python\Python313\Lib\http\client.py", line 331, in begin
    version, status, reason = self._read_status()
                              ~~~~~~~~~~~~~~~~~^^
  File "C:\Users\int.nimeth\AppData\Local\Programs\Python\Python313\Lib\http\client.py", line 292, in _read_status
    line = str(self.fp.readline(_MAXLINE + 1), "iso-8859-1")
               ~~~~~~~~~~~~~~~~^^^^^^^^^^^^^^
  File "C:\Users\int.nimeth\AppData\Local\Programs\Python\Python313\Lib\socket.py", line 719, in readinto
    return self._sock.recv_into(b)
           ~~~~~~~~~~~~~~~~~~~~^^^
TimeoutError: timed out

The above exception was the direct cause of the following exception:

Traceback (most recent call last):
  File "C:\Users\int.nimeth\AppData\Local\Programs\Python\Python313\Lib\site-packages\requests\adapters.py", line 667, in send
    resp = conn.urlopen(
        method=request.method,
    ...<9 lines>...
        chunked=chunked,
    )
  File "C:\Users\int.nimeth\AppData\Local\Programs\Python\Python313\Lib\site-packages\urllib3\connectionpool.py", line 841, in urlopen
    retries = retries.increment(
        method, url, error=new_e, _pool=self, _stacktrace=sys.exc_info()[2]
    )
  File "C:\Users\int.nimeth\AppData\Local\Programs\Python\Python313\Lib\site-packages\urllib3\util\retry.py", line 474, in increment
    raise reraise(type(error), error, _stacktrace)
          ~~~~~~~^^^^^^^^^^^^^^^^^^^^^^^^^^^^^^^^^
  File "C:\Users\int.nimeth\AppData\Local\Programs\Python\Python313\Lib\site-packages\urllib3\util\util.py", line 39, in reraise
    raise value
  File "C:\Users\int.nimeth\AppData\Local\Programs\Python\Python313\Lib\site-packages\urllib3\connectionpool.py", line 787, in urlopen
    response = self._make_request(
        conn,
    ...<10 lines>...
        **response_kw,
    )
  File "C:\Users\int.nimeth\AppData\Local\Programs\Python\Python313\Lib\site-packages\urllib3\connectionpool.py", line 536, in _make_request
    self._raise_timeout(err=e, url=url, timeout_value=read_timeout)
    ~~~~~~~~~~~~~~~~~~~^^^^^^^^^^^^^^^^^^^^^^^^^^^^^^^^^^^^^^^^^^^^
  File "C:\Users\int.nimeth\AppData\Local\Programs\Python\Python313\Lib\site-packages\urllib3\connectionpool.py", line 367, in _raise_timeout
    raise ReadTimeoutError(
        self, url, f"Read timed out. (read timeout={timeout_value})"
    ) from err
urllib3.exceptions.ReadTimeoutError: HTTPConnectionPool(host='localhost', port=5113): Read timed out. (read timeout=10)

During handling of the above exception, another exception occurred:

Traceback (most recent call last):
  File "C:\Users\int.nimeth\Desktop\codePuls_collector\services\backend\save_organization_data_service.py", line 9, in save_organization_data_service
    response = requests.post(
        USER_API["create_project"],
    ...<2 lines>...
        timeout=10
    )
  File "C:\Users\int.nimeth\AppData\Local\Programs\Python\Python313\Lib\site-packages\requests\api.py", line 115, in post
    return request("post", url, data=data, json=json, **kwargs)
  File "C:\Users\int.nimeth\AppData\Local\Programs\Python\Python313\Lib\site-packages\requests\api.py", line 59, in request
    return session.request(method=method, url=url, **kwargs)
           ~~~~~~~~~~~~~~~^^^^^^^^^^^^^^^^^^^^^^^^^^^^^^^^^^
  File "C:\Users\int.nimeth\AppData\Local\Programs\Python\Python313\Lib\site-packages\requests\sessions.py", line 589, in request
    resp = self.send(prep, **send_kwargs)
  File "C:\Users\int.nimeth\AppData\Local\Programs\Python\Python313\Lib\site-packages\requests\sessions.py", line 703, in send
    r = adapter.send(request, **kwargs)
  File "C:\Users\int.nimeth\AppData\Local\Programs\Python\Python313\Lib\site-packages\requests\adapters.py", line 713, in send
    raise ReadTimeout(e, request=request)
requests.exceptions.ReadTimeout: HTTPConnectionPool(host='localhost', port=5113): Read timed out. (read timeout=10)
2025-07-14 09:33:46 - INFO - Application started
2025-07-14 09:39:48 - INFO - Application started
2025-07-14 09:51:42 - INFO - Application started
2025-07-14 09:54:10 - INFO - Application started
2025-07-14 09:54:10 - ERROR - Failed to load tabs
Traceback (most recent call last):
  File "C:\Users\int.nimeth\Desktop\codePuls_collector\app.py", line 51, in setup_tabs
    from tabs.project_tab import setup_project_tab
  File "C:\Users\int.nimeth\Desktop\codePuls_collector\tabs\project_tab.py", line 17, in <module>
    from providers import ProviderFactory, ProviderType
  File "C:\Users\int.nimeth\Desktop\codePuls_collector\providers\__init__.py", line 2, in <module>
    from .github_provider import GitHubProvider
  File "C:\Users\int.nimeth\Desktop\codePuls_collector\providers\github_provider.py", line 8, in <module>
    from services.github.get_user_data_service import get_user_data_service
  File "C:\Users\int.nimeth\Desktop\codePuls_collector\services\github\get_user_data_service.py", line 50
    displayName                "userCreatedAt": data.get("created_at"),
              ^
SyntaxError: ':' expected after dictionary key
2025-07-14 09:54:10 - ERROR - Unhandled exception occurred
Traceback (most recent call last):
  File "C:\Users\int.nimeth\Desktop\codePuls_collector\app.py", line 51, in setup_tabs
    from tabs.project_tab import setup_project_tab
  File "C:\Users\int.nimeth\Desktop\codePuls_collector\tabs\project_tab.py", line 17, in <module>
    from providers import ProviderFactory, ProviderType
  File "C:\Users\int.nimeth\Desktop\codePuls_collector\providers\__init__.py", line 2, in <module>
    from .github_provider import GitHubProvider
  File "C:\Users\int.nimeth\Desktop\codePuls_collector\providers\github_provider.py", line 8, in <module>
    from services.github.get_user_data_service import get_user_data_service
  File "C:\Users\int.nimeth\Desktop\codePuls_collector\services\github\get_user_data_service.py", line 50
    displayName                "userCreatedAt": data.get("created_at"),
              ^
SyntaxError: ':' expected after dictionary key

During handling of the above exception, another exception occurred:

Traceback (most recent call last):
  File "C:\Users\int.nimeth\Desktop\codePuls_collector\main.py", line 12, in main
    window = SourceProviderTool()
  File "C:\Users\int.nimeth\Desktop\codePuls_collector\app.py", line 16, in __init__
    self.init_ui()
    ~~~~~~~~~~~~^^
  File "C:\Users\int.nimeth\Desktop\codePuls_collector\app.py", line 40, in init_ui
    self.setup_tabs()
    ~~~~~~~~~~~~~~~^^
  File "C:\Users\int.nimeth\Desktop\codePuls_collector\app.py", line 69, in setup_tabs
    show_error_message(str(e))
    ~~~~~~~~~~~~~~~~~~^^^^^^^^
TypeError: show_error_message() missing 1 required positional argument: 'error'
2025-07-14 09:54:45 - INFO - Application started
2025-07-14 10:03:53 - INFO - Application started
2025-07-15 10:37:53 - INFO - Application started
2025-07-15 11:16:57 - INFO - Application started
2025-07-15 11:19:01 - INFO - Application started
2025-07-15 11:22:44 - INFO - Application started
2025-07-16 09:34:07 - INFO - Application started
2025-07-16 09:35:39 - ERROR - Network error occurred during API request
Traceback (most recent call last):
  File "C:\Users\int.nimeth\AppData\Local\Programs\Python\Python313\Lib\site-packages\urllib3\connection.py", line 198, in _new_conn
    sock = connection.create_connection(
        (self._dns_host, self.port),
    ...<2 lines>...
        socket_options=self.socket_options,
    )
  File "C:\Users\int.nimeth\AppData\Local\Programs\Python\Python313\Lib\site-packages\urllib3\util\connection.py", line 85, in create_connection
    raise err
  File "C:\Users\int.nimeth\AppData\Local\Programs\Python\Python313\Lib\site-packages\urllib3\util\connection.py", line 73, in create_connection
    sock.connect(sa)
    ~~~~~~~~~~~~^^^^
ConnectionRefusedError: [WinError 10061] No connection could be made because the target machine actively refused it

The above exception was the direct cause of the following exception:

Traceback (most recent call last):
  File "C:\Users\int.nimeth\AppData\Local\Programs\Python\Python313\Lib\site-packages\urllib3\connectionpool.py", line 787, in urlopen
    response = self._make_request(
        conn,
    ...<10 lines>...
        **response_kw,
    )
  File "C:\Users\int.nimeth\AppData\Local\Programs\Python\Python313\Lib\site-packages\urllib3\connectionpool.py", line 493, in _make_request
    conn.request(
    ~~~~~~~~~~~~^
        method,
        ^^^^^^^
    ...<6 lines>...
        enforce_content_length=enforce_content_length,
        ^^^^^^^^^^^^^^^^^^^^^^^^^^^^^^^^^^^^^^^^^^^^^^
    )
    ^
  File "C:\Users\int.nimeth\AppData\Local\Programs\Python\Python313\Lib\site-packages\urllib3\connection.py", line 445, in request
    self.endheaders()
    ~~~~~~~~~~~~~~~^^
  File "C:\Users\int.nimeth\AppData\Local\Programs\Python\Python313\Lib\http\client.py", line 1333, in endheaders
    self._send_output(message_body, encode_chunked=encode_chunked)
    ~~~~~~~~~~~~~~~~~^^^^^^^^^^^^^^^^^^^^^^^^^^^^^^^^^^^^^^^^^^^^^
  File "C:\Users\int.nimeth\AppData\Local\Programs\Python\Python313\Lib\http\client.py", line 1093, in _send_output
    self.send(msg)
    ~~~~~~~~~^^^^^
  File "C:\Users\int.nimeth\AppData\Local\Programs\Python\Python313\Lib\http\client.py", line 1037, in send
    self.connect()
    ~~~~~~~~~~~~^^
  File "C:\Users\int.nimeth\AppData\Local\Programs\Python\Python313\Lib\site-packages\urllib3\connection.py", line 276, in connect
    self.sock = self._new_conn()
                ~~~~~~~~~~~~~~^^
  File "C:\Users\int.nimeth\AppData\Local\Programs\Python\Python313\Lib\site-packages\urllib3\connection.py", line 213, in _new_conn
    raise NewConnectionError(
        self, f"Failed to establish a new connection: {e}"
    ) from e
urllib3.exceptions.NewConnectionError: <urllib3.connection.HTTPConnection object at 0x000001976AC36660>: Failed to establish a new connection: [WinError 10061] No connection could be made because the target machine actively refused it

The above exception was the direct cause of the following exception:

Traceback (most recent call last):
  File "C:\Users\int.nimeth\AppData\Local\Programs\Python\Python313\Lib\site-packages\requests\adapters.py", line 667, in send
    resp = conn.urlopen(
        method=request.method,
    ...<9 lines>...
        chunked=chunked,
    )
  File "C:\Users\int.nimeth\AppData\Local\Programs\Python\Python313\Lib\site-packages\urllib3\connectionpool.py", line 841, in urlopen
    retries = retries.increment(
        method, url, error=new_e, _pool=self, _stacktrace=sys.exc_info()[2]
    )
  File "C:\Users\int.nimeth\AppData\Local\Programs\Python\Python313\Lib\site-packages\urllib3\util\retry.py", line 519, in increment
    raise MaxRetryError(_pool, url, reason) from reason  # type: ignore[arg-type]
    ^^^^^^^^^^^^^^^^^^^^^^^^^^^^^^^^^^^^^^^^^^^^^^^^^^^
urllib3.exceptions.MaxRetryError: HTTPConnectionPool(host='localhost', port=5113): Max retries exceeded with url: /api/project (Caused by NewConnectionError('<urllib3.connection.HTTPConnection object at 0x000001976AC36660>: Failed to establish a new connection: [WinError 10061] No connection could be made because the target machine actively refused it'))

During handling of the above exception, another exception occurred:

Traceback (most recent call last):
  File "C:\Users\int.nimeth\Desktop\codePuls_collector\services\backend\save_organization_data_service.py", line 9, in save_organization_data_service
    response = requests.post(
        USER_API["create_project"],
    ...<2 lines>...
        timeout=10
    )
  File "C:\Users\int.nimeth\AppData\Local\Programs\Python\Python313\Lib\site-packages\requests\api.py", line 115, in post
    return request("post", url, data=data, json=json, **kwargs)
  File "C:\Users\int.nimeth\AppData\Local\Programs\Python\Python313\Lib\site-packages\requests\api.py", line 59, in request
    return session.request(method=method, url=url, **kwargs)
           ~~~~~~~~~~~~~~~^^^^^^^^^^^^^^^^^^^^^^^^^^^^^^^^^^
  File "C:\Users\int.nimeth\AppData\Local\Programs\Python\Python313\Lib\site-packages\requests\sessions.py", line 589, in request
    resp = self.send(prep, **send_kwargs)
  File "C:\Users\int.nimeth\AppData\Local\Programs\Python\Python313\Lib\site-packages\requests\sessions.py", line 703, in send
    r = adapter.send(request, **kwargs)
  File "C:\Users\int.nimeth\AppData\Local\Programs\Python\Python313\Lib\site-packages\requests\adapters.py", line 700, in send
    raise ConnectionError(e, request=request)
requests.exceptions.ConnectionError: HTTPConnectionPool(host='localhost', port=5113): Max retries exceeded with url: /api/project (Caused by NewConnectionError('<urllib3.connection.HTTPConnection object at 0x000001976AC36660>: Failed to establish a new connection: [WinError 10061] No connection could be made because the target machine actively refused it'))
2025-07-16 10:08:01 - INFO - Application started
2025-07-16 10:09:02 - INFO - Application started
2025-07-16 10:52:28 - INFO - Application started
2025-07-16 10:55:29 - INFO - Application started
2025-07-16 10:56:41 - INFO - Application started
